Watching for file changes with StatReloader
C:\Users\user\Documents\react-tailwind\backendMtaawetuApi\backendMtaawetuApi\settings.py changed, reloading.
Watching for file changes with StatReloader
C:\Users\user\Documents\react-tailwind\backendMtaawetuApi\backendMtaawetuApi\settings.py changed, reloading.
Watching for file changes with StatReloader
Watching for file changes with StatReloader
"OPTIONS /api/auth/register/ HTTP/1.1" 200 0
Not Found: /api/auth/register/
"POST /api/auth/register/ HTTP/1.1" 404 6087
C:\Users\user\Documents\react-tailwind\backendMtaawetuApi\coreApi\urls.py changed, reloading.
Watching for file changes with StatReloader
Internal Server Error: /api/auth/register/
Traceback (most recent call last):
  File "C:\Users\user\Documents\react-tailwind\Lib\site-packages\django\db\backends\utils.py", line 105, in _execute
    return self.cursor.execute(sql, params)
           ^^^^^^^^^^^^^^^^^^^^^^^^^^^^^^^^
psycopg2.errors.UndefinedTable: relation "coreApi_customuser" does not exist
LINE 1: SELECT 1 AS "a" FROM "coreApi_customuser" WHERE "coreApi_cus...
                             ^


The above exception was the direct cause of the following exception:

Traceback (most recent call last):
  File "C:\Users\user\Documents\react-tailwind\Lib\site-packages\django\core\handlers\exception.py", line 55, in inner
    response = get_response(request)
               ^^^^^^^^^^^^^^^^^^^^^
  File "C:\Users\user\Documents\react-tailwind\Lib\site-packages\django\core\handlers\base.py", line 197, in _get_response
    response = wrapped_callback(request, *callback_args, **callback_kwargs)
               ^^^^^^^^^^^^^^^^^^^^^^^^^^^^^^^^^^^^^^^^^^^^^^^^^^^^^^^^^^^^
  File "C:\Users\user\Documents\react-tailwind\Lib\site-packages\django\views\decorators\csrf.py", line 65, in _view_wrapper
    return view_func(request, *args, **kwargs)
           ^^^^^^^^^^^^^^^^^^^^^^^^^^^^^^^^^^^
  File "C:\Users\user\Documents\react-tailwind\Lib\site-packages\django\views\generic\base.py", line 104, in view
    return self.dispatch(request, *args, **kwargs)
           ^^^^^^^^^^^^^^^^^^^^^^^^^^^^^^^^^^^^^^^
  File "C:\Users\user\Documents\react-tailwind\Lib\site-packages\rest_framework\views.py", line 509, in dispatch
    response = self.handle_exception(exc)
               ^^^^^^^^^^^^^^^^^^^^^^^^^^
  File "C:\Users\user\Documents\react-tailwind\Lib\site-packages\rest_framework\views.py", line 469, in handle_exception
    self.raise_uncaught_exception(exc)
  File "C:\Users\user\Documents\react-tailwind\Lib\site-packages\rest_framework\views.py", line 480, in raise_uncaught_exception
    raise exc
  File "C:\Users\user\Documents\react-tailwind\Lib\site-packages\rest_framework\views.py", line 506, in dispatch
    response = handler(request, *args, **kwargs)
               ^^^^^^^^^^^^^^^^^^^^^^^^^^^^^^^^^
  File "C:\Users\user\Documents\react-tailwind\Lib\site-packages\rest_framework\decorators.py", line 50, in handler
    return func(*args, **kwargs)
           ^^^^^^^^^^^^^^^^^^^^^
  File "C:\Users\user\Documents\react-tailwind\backendMtaawetuApi\coreApi\views.py", line 47, in register_user
    if serializer.is_valid():
       ^^^^^^^^^^^^^^^^^^^^^
  File "C:\Users\user\Documents\react-tailwind\Lib\site-packages\rest_framework\serializers.py", line 223, in is_valid
    self._validated_data = self.run_validation(self.initial_data)
                           ^^^^^^^^^^^^^^^^^^^^^^^^^^^^^^^^^^^^^^
  File "C:\Users\user\Documents\react-tailwind\Lib\site-packages\rest_framework\serializers.py", line 442, in run_validation
    value = self.to_internal_value(data)
            ^^^^^^^^^^^^^^^^^^^^^^^^^^^^
  File "C:\Users\user\Documents\react-tailwind\Lib\site-packages\rest_framework\serializers.py", line 499, in to_internal_value
    validated_value = field.run_validation(primitive_value)
                      ^^^^^^^^^^^^^^^^^^^^^^^^^^^^^^^^^^^^^
  File "C:\Users\user\Documents\react-tailwind\Lib\site-packages\rest_framework\fields.py", line 757, in run_validation
    return super().run_validation(data)
           ^^^^^^^^^^^^^^^^^^^^^^^^^^^^
  File "C:\Users\user\Documents\react-tailwind\Lib\site-packages\rest_framework\fields.py", line 539, in run_validation
    self.run_validators(value)
  File "C:\Users\user\Documents\react-tailwind\Lib\site-packages\rest_framework\fields.py", line 551, in run_validators
    validator(value, self)
  File "C:\Users\user\Documents\react-tailwind\Lib\site-packages\rest_framework\validators.py", line 73, in __call__
    if qs_exists(queryset):
       ^^^^^^^^^^^^^^^^^^^
  File "C:\Users\user\Documents\react-tailwind\Lib\site-packages\rest_framework\validators.py", line 21, in qs_exists
    return queryset.exists()
           ^^^^^^^^^^^^^^^^^
  File "C:\Users\user\Documents\react-tailwind\Lib\site-packages\django\db\models\query.py", line 1288, in exists
    return self.query.has_results(using=self.db)
           ^^^^^^^^^^^^^^^^^^^^^^^^^^^^^^^^^^^^^
  File "C:\Users\user\Documents\react-tailwind\Lib\site-packages\django\db\models\sql\query.py", line 660, in has_results
    return compiler.has_results()
           ^^^^^^^^^^^^^^^^^^^^^^
  File "C:\Users\user\Documents\react-tailwind\Lib\site-packages\django\db\models\sql\compiler.py", line 1542, in has_results
    return bool(self.execute_sql(SINGLE))
                ^^^^^^^^^^^^^^^^^^^^^^^^
  File "C:\Users\user\Documents\react-tailwind\Lib\site-packages\django\db\models\sql\compiler.py", line 1574, in execute_sql
    cursor.execute(sql, params)
  File "C:\Users\user\Documents\react-tailwind\Lib\site-packages\django\db\backends\utils.py", line 122, in execute
    return super().execute(sql, params)
           ^^^^^^^^^^^^^^^^^^^^^^^^^^^^
  File "C:\Users\user\Documents\react-tailwind\Lib\site-packages\django\db\backends\utils.py", line 79, in execute
    return self._execute_with_wrappers(
           ^^^^^^^^^^^^^^^^^^^^^^^^^^^^
  File "C:\Users\user\Documents\react-tailwind\Lib\site-packages\django\db\backends\utils.py", line 92, in _execute_with_wrappers
    return executor(sql, params, many, context)
           ^^^^^^^^^^^^^^^^^^^^^^^^^^^^^^^^^^^^
  File "C:\Users\user\Documents\react-tailwind\Lib\site-packages\django\db\backends\utils.py", line 100, in _execute
    with self.db.wrap_database_errors:
         ^^^^^^^^^^^^^^^^^^^^^^^^^^^^
  File "C:\Users\user\Documents\react-tailwind\Lib\site-packages\django\db\utils.py", line 91, in __exit__
    raise dj_exc_value.with_traceback(traceback) from exc_value
  File "C:\Users\user\Documents\react-tailwind\Lib\site-packages\django\db\backends\utils.py", line 105, in _execute
    return self.cursor.execute(sql, params)
           ^^^^^^^^^^^^^^^^^^^^^^^^^^^^^^^^
django.db.utils.ProgrammingError: relation "coreApi_customuser" does not exist
LINE 1: SELECT 1 AS "a" FROM "coreApi_customuser" WHERE "coreApi_cus...
                             ^

"POST /api/auth/register/ HTTP/1.1" 500 195764
Watching for file changes with StatReloader
Watching for file changes with StatReloader
Bad Request: /api/auth/register/
"POST /api/auth/register/ HTTP/1.1" 400 151
Watching for file changes with StatReloader
Bad Request: /api/auth/register/
"POST /api/auth/register/ HTTP/1.1" 400 151
Bad Request: /api/auth/register/
"POST /api/auth/register/ HTTP/1.1" 400 151
C:\Users\user\Documents\react-tailwind\backendMtaawetuApi\coreApi\admin.py changed, reloading.
Watching for file changes with StatReloader
Watching for file changes with StatReloader
"GET /admin/ HTTP/1.1" 302 0
"GET /admin/login/?next=/admin/ HTTP/1.1" 200 4157
"GET /static/admin/css/dark_mode.css HTTP/1.1" 200 2804
"GET /static/admin/css/base.css HTTP/1.1" 200 22092
"GET /static/admin/css/responsive.css HTTP/1.1" 200 17972
"GET /static/admin/css/login.css HTTP/1.1" 200 951
"GET /static/admin/css/nav_sidebar.css HTTP/1.1" 200 2810
"GET /static/admin/js/theme.js HTTP/1.1" 200 1653
"GET /static/admin/js/nav_sidebar.js HTTP/1.1" 200 3063
Not Found: /favicon.ico
"GET /favicon.ico HTTP/1.1" 404 2667
"POST /admin/login/?next=/admin/ HTTP/1.1" 200 4316
"POST /admin/login/?next=/admin/ HTTP/1.1" 200 4314
Watching for file changes with StatReloader
"POST /admin/login/?next=/admin/ HTTP/1.1" 200 4314
"POST /admin/login/?next=/admin/ HTTP/1.1" 200 4314
"POST /admin/login/?next=/admin/ HTTP/1.1" 302 0
"GET /admin/ HTTP/1.1" 200 14303
"GET /static/admin/css/dashboard.css HTTP/1.1" 200 441
"GET /static/admin/img/icon-deletelink.svg HTTP/1.1" 200 392
"GET /static/admin/img/icon-changelink.svg HTTP/1.1" 200 380
"GET /static/admin/img/icon-addlink.svg HTTP/1.1" 200 331
"GET /admin/coreApi/customuser/ HTTP/1.1" 200 16030
"GET /static/admin/css/changelists.css HTTP/1.1" 200 6878
"GET /static/admin/js/jquery.init.js HTTP/1.1" 200 347
"GET /static/admin/js/core.js HTTP/1.1" 200 6208
"GET /static/admin/js/actions.js HTTP/1.1" 200 8076
"GET /static/admin/js/urlify.js HTTP/1.1" 200 7887
"GET /static/admin/js/admin/RelatedObjectLookups.js HTTP/1.1" 200 9097
"GET /static/admin/img/search.svg HTTP/1.1" 200 458
"GET /static/admin/img/icon-no.svg HTTP/1.1" 200 560
"GET /static/admin/js/prepopulate.js HTTP/1.1" 200 1531
"GET /static/admin/img/icon-yes.svg HTTP/1.1" 200 436
"GET /static/admin/js/vendor/jquery/jquery.js HTTP/1.1" 200 285314
"GET /static/admin/js/vendor/xregexp/xregexp.js HTTP/1.1" 200 325171
"GET /static/admin/js/filters.js HTTP/1.1" 200 978
"GET /admin/jsi18n/ HTTP/1.1" 200 3342
"GET /static/admin/img/tooltag-add.svg HTTP/1.1" 200 331
"GET /static/admin/img/icon-viewlink.svg HTTP/1.1" 200 581
"OPTIONS /api/auth/login/ HTTP/1.1" 200 0
"POST /api/auth/login/ HTTP/1.1" 200 803
"POST /api/auth/login/ HTTP/1.1" 200 803
"POST /api/auth/login/ HTTP/1.1" 200 803
"OPTIONS /api/user/profile/ HTTP/1.1" 200 0
"OPTIONS /api/user/profile/ HTTP/1.1" 200 0
"GET /api/user/profile/ HTTP/1.1" 200 272
"GET /api/user/profile/ HTTP/1.1" 200 272
Bad Request: /api/auth/login/
"POST /api/auth/login/ HTTP/1.1" 400 44
Bad Request: /api/auth/login/
"POST /api/auth/login/ HTTP/1.1" 400 44
"POST /api/auth/login/ HTTP/1.1" 200 803
"POST /api/auth/login/ HTTP/1.1" 200 803
"GET /api/user/profile/ HTTP/1.1" 200 272
"GET /api/user/profile/ HTTP/1.1" 200 272
"GET /api/user/profile/ HTTP/1.1" 200 272
"GET /api/user/profile/ HTTP/1.1" 200 272
"GET /api/user/profile/ HTTP/1.1" 200 272
"GET /api/user/profile/ HTTP/1.1" 200 272
"GET /api/user/profile/ HTTP/1.1" 200 272
"GET /api/user/profile/ HTTP/1.1" 200 272
"OPTIONS /api/auth/login/ HTTP/1.1" 200 0
"POST /api/auth/login/ HTTP/1.1" 200 803
"GET /admin/mapdatacontroler/maplayer/ HTTP/1.1" 200 15216
"GET /admin/jsi18n/ HTTP/1.1" 200 3342
"GET /admin/coreApi/package/ HTTP/1.1" 200 17022
"GET /admin/jsi18n/ HTTP/1.1" 200 3342
"GET /static/admin/img/sorting-icons.svg HTTP/1.1" 200 1097
"GET /admin/coreApi/payment/ HTTP/1.1" 200 13843
"GET /admin/jsi18n/ HTTP/1.1" 200 3342
"GET /admin/coreApi/package/ HTTP/1.1" 200 17022
"GET /admin/jsi18n/ HTTP/1.1" 200 3342
Unauthorized: /api/user/profile/
"GET /api/user/profile/ HTTP/1.1" 401 172
Unauthorized: /api/user/profile/
"GET /api/user/profile/ HTTP/1.1" 401 172
"OPTIONS /api/token/refresh/ HTTP/1.1" 200 0
"OPTIONS /api/token/refresh/ HTTP/1.1" 200 0
Internal Server Error: /api/token/refresh/
Traceback (most recent call last):
  File "C:\Users\user\Documents\react-tailwind\Lib\site-packages\django\core\handlers\exception.py", line 55, in inner
    response = get_response(request)
               ^^^^^^^^^^^^^^^^^^^^^
  File "C:\Users\user\Documents\react-tailwind\Lib\site-packages\django\core\handlers\base.py", line 197, in _get_response
    response = wrapped_callback(request, *callback_args, **callback_kwargs)
               ^^^^^^^^^^^^^^^^^^^^^^^^^^^^^^^^^^^^^^^^^^^^^^^^^^^^^^^^^^^^
  File "C:\Users\user\Documents\react-tailwind\Lib\site-packages\django\views\decorators\csrf.py", line 65, in _view_wrapper
    return view_func(request, *args, **kwargs)
           ^^^^^^^^^^^^^^^^^^^^^^^^^^^^^^^^^^^
  File "C:\Users\user\Documents\react-tailwind\Lib\site-packages\django\views\generic\base.py", line 104, in view
    return self.dispatch(request, *args, **kwargs)
           ^^^^^^^^^^^^^^^^^^^^^^^^^^^^^^^^^^^^^^^
  File "C:\Users\user\Documents\react-tailwind\Lib\site-packages\rest_framework\views.py", line 509, in dispatch
    response = self.handle_exception(exc)
               ^^^^^^^^^^^^^^^^^^^^^^^^^^
  File "C:\Users\user\Documents\react-tailwind\Lib\site-packages\rest_framework\views.py", line 469, in handle_exception
    self.raise_uncaught_exception(exc)
  File "C:\Users\user\Documents\react-tailwind\Lib\site-packages\rest_framework\views.py", line 480, in raise_uncaught_exception
    raise exc
  File "C:\Users\user\Documents\react-tailwind\Lib\site-packages\rest_framework\views.py", line 506, in dispatch
    response = handler(request, *args, **kwargs)
               ^^^^^^^^^^^^^^^^^^^^^^^^^^^^^^^^^
  File "C:\Users\user\Documents\react-tailwind\Lib\site-packages\rest_framework_simplejwt\views.py", line 44, in post
    serializer.is_valid(raise_exception=True)
  File "C:\Users\user\Documents\react-tailwind\Lib\site-packages\rest_framework\serializers.py", line 223, in is_valid
    self._validated_data = self.run_validation(self.initial_data)
                           ^^^^^^^^^^^^^^^^^^^^^^^^^^^^^^^^^^^^^^
  File "C:\Users\user\Documents\react-tailwind\Lib\site-packages\rest_framework\serializers.py", line 445, in run_validation
    value = self.validate(value)
            ^^^^^^^^^^^^^^^^^^^^
  File "C:\Users\user\Documents\react-tailwind\Lib\site-packages\rest_framework_simplejwt\serializers.py", line 141, in validate
    refresh.outstand()
  File "C:\Users\user\Documents\react-tailwind\Lib\site-packages\rest_framework_simplejwt\tokens.py", line 222, in outstand
    return OutstandingToken.objects.get_or_create(
           ^^^^^^^^^^^^^^^^^^^^^^^^
AttributeError: type object 'OutstandingToken' has no attribute 'objects'
"POST /api/token/refresh/ HTTP/1.1" 500 120931
Internal Server Error: /api/token/refresh/
Traceback (most recent call last):
  File "C:\Users\user\Documents\react-tailwind\Lib\site-packages\django\core\handlers\exception.py", line 55, in inner
    response = get_response(request)
               ^^^^^^^^^^^^^^^^^^^^^
  File "C:\Users\user\Documents\react-tailwind\Lib\site-packages\django\core\handlers\base.py", line 197, in _get_response
    response = wrapped_callback(request, *callback_args, **callback_kwargs)
               ^^^^^^^^^^^^^^^^^^^^^^^^^^^^^^^^^^^^^^^^^^^^^^^^^^^^^^^^^^^^
  File "C:\Users\user\Documents\react-tailwind\Lib\site-packages\django\views\decorators\csrf.py", line 65, in _view_wrapper
    return view_func(request, *args, **kwargs)
           ^^^^^^^^^^^^^^^^^^^^^^^^^^^^^^^^^^^
  File "C:\Users\user\Documents\react-tailwind\Lib\site-packages\django\views\generic\base.py", line 104, in view
    return self.dispatch(request, *args, **kwargs)
           ^^^^^^^^^^^^^^^^^^^^^^^^^^^^^^^^^^^^^^^
  File "C:\Users\user\Documents\react-tailwind\Lib\site-packages\rest_framework\views.py", line 509, in dispatch
    response = self.handle_exception(exc)
               ^^^^^^^^^^^^^^^^^^^^^^^^^^
  File "C:\Users\user\Documents\react-tailwind\Lib\site-packages\rest_framework\views.py", line 469, in handle_exception
    self.raise_uncaught_exception(exc)
  File "C:\Users\user\Documents\react-tailwind\Lib\site-packages\rest_framework\views.py", line 480, in raise_uncaught_exception
    raise exc
  File "C:\Users\user\Documents\react-tailwind\Lib\site-packages\rest_framework\views.py", line 506, in dispatch
    response = handler(request, *args, **kwargs)
               ^^^^^^^^^^^^^^^^^^^^^^^^^^^^^^^^^
  File "C:\Users\user\Documents\react-tailwind\Lib\site-packages\rest_framework_simplejwt\views.py", line 44, in post
    serializer.is_valid(raise_exception=True)
  File "C:\Users\user\Documents\react-tailwind\Lib\site-packages\rest_framework\serializers.py", line 223, in is_valid
    self._validated_data = self.run_validation(self.initial_data)
                           ^^^^^^^^^^^^^^^^^^^^^^^^^^^^^^^^^^^^^^
  File "C:\Users\user\Documents\react-tailwind\Lib\site-packages\rest_framework\serializers.py", line 445, in run_validation
    value = self.validate(value)
            ^^^^^^^^^^^^^^^^^^^^
  File "C:\Users\user\Documents\react-tailwind\Lib\site-packages\rest_framework_simplejwt\serializers.py", line 141, in validate
    refresh.outstand()
  File "C:\Users\user\Documents\react-tailwind\Lib\site-packages\rest_framework_simplejwt\tokens.py", line 222, in outstand
    return OutstandingToken.objects.get_or_create(
           ^^^^^^^^^^^^^^^^^^^^^^^^
AttributeError: type object 'OutstandingToken' has no attribute 'objects'
"POST /api/token/refresh/ HTTP/1.1" 500 120931
"POST /api/auth/login/ HTTP/1.1" 200 803
"OPTIONS /api/user/dashboard/ HTTP/1.1" 200 0
"OPTIONS /api/packages/ HTTP/1.1" 200 0
"OPTIONS /api/payments/history/ HTTP/1.1" 200 0
"OPTIONS /api/user/dashboard/ HTTP/1.1" 200 0
"OPTIONS /api/packages/ HTTP/1.1" 200 0
"OPTIONS /api/payments/history/ HTTP/1.1" 200 0
"GET /api/packages/ HTTP/1.1" 200 849
"GET /api/payments/history/ HTTP/1.1" 200 2
"GET /api/user/dashboard/ HTTP/1.1" 200 375
"GET /api/payments/history/ HTTP/1.1" 200 2
"GET /api/user/dashboard/ HTTP/1.1" 200 375
"GET /api/packages/ HTTP/1.1" 200 849
"GET /api/payments/history/ HTTP/1.1" 200 2
"GET /api/user/profile/ HTTP/1.1" 200 272
"GET /api/packages/ HTTP/1.1" 200 849
"GET /api/user/dashboard/ HTTP/1.1" 200 375
"GET /api/packages/ HTTP/1.1" 200 849
"GET /api/payments/history/ HTTP/1.1" 200 2
"GET /api/user/profile/ HTTP/1.1" 200 272
"GET /api/user/dashboard/ HTTP/1.1" 200 375
"GET /api/user/profile/ HTTP/1.1" 200 272
"GET /api/payments/history/ HTTP/1.1" 200 2
"GET /api/user/dashboard/ HTTP/1.1" 200 375
"GET /api/packages/ HTTP/1.1" 200 849
"GET /api/user/profile/ HTTP/1.1" 200 272
"GET /api/payments/history/ HTTP/1.1" 200 2
"GET /api/user/dashboard/ HTTP/1.1" 200 375
"GET /api/packages/ HTTP/1.1" 200 849
"GET /api/user/profile/ HTTP/1.1" 200 272
"GET /api/packages/ HTTP/1.1" 200 849
"GET /api/payments/history/ HTTP/1.1" 200 2
"GET /api/user/dashboard/ HTTP/1.1" 200 375
"GET /api/user/profile/ HTTP/1.1" 200 272
"GET /api/packages/ HTTP/1.1" 200 849
"GET /api/payments/history/ HTTP/1.1" 200 2
"GET /api/user/dashboard/ HTTP/1.1" 200 375
"GET /api/user/profile/ HTTP/1.1" 200 272
"GET /api/user/profile/ HTTP/1.1" 200 272
"GET /api/packages/ HTTP/1.1" 200 849
"GET /api/user/dashboard/ HTTP/1.1" 200 375
"GET /api/payments/history/ HTTP/1.1" 200 2
"GET /api/packages/ HTTP/1.1" 200 849
"GET /api/payments/history/ HTTP/1.1" 200 2
"GET /api/user/dashboard/ HTTP/1.1" 200 375
"GET /api/user/profile/ HTTP/1.1" 200 272
"GET /api/user/profile/ HTTP/1.1" 200 272
"GET /api/packages/ HTTP/1.1" 200 849
"GET /api/payments/history/ HTTP/1.1" 200 2
"GET /api/user/dashboard/ HTTP/1.1" 200 375
"GET /api/packages/ HTTP/1.1" 200 849
"GET /api/payments/history/ HTTP/1.1" 200 2
"GET /api/user/dashboard/ HTTP/1.1" 200 375
"OPTIONS /api/auth/logout/ HTTP/1.1" 200 0
Not Found: /api/auth/logout/
"POST /api/auth/logout/ HTTP/1.1" 404 6037
Not Found: /api/auth/logout/
"POST /api/auth/logout/ HTTP/1.1" 404 6037
Not Found: /api/auth/logout/
"POST /api/auth/logout/ HTTP/1.1" 404 6037
Not Found: /api/auth/logout/
"POST /api/auth/logout/ HTTP/1.1" 404 6037
Not Found: /api/auth/logout/
"POST /api/auth/logout/ HTTP/1.1" 404 6037
Not Found: /api/auth/logout/
"POST /api/auth/logout/ HTTP/1.1" 404 6037
Not Found: /api/auth/logout/
"POST /api/auth/logout/ HTTP/1.1" 404 6037
Not Found: /api/auth/logout/
"POST /api/auth/logout/ HTTP/1.1" 404 6037
"OPTIONS /api/auth/register/ HTTP/1.1" 200 0
"POST /api/auth/register/ HTTP/1.1" 201 1078
"GET /api/payments/history/ HTTP/1.1" 200 2
"GET /api/packages/ HTTP/1.1" 200 849
"GET /api/user/dashboard/ HTTP/1.1" 200 639
"GET /api/packages/ HTTP/1.1" 200 849
"GET /api/payments/history/ HTTP/1.1" 200 2
"GET /api/user/dashboard/ HTTP/1.1" 200 639
"GET /api/user/profile/ HTTP/1.1" 200 535
"GET /api/user/profile/ HTTP/1.1" 200 535
"GET /api/packages/ HTTP/1.1" 200 849
"GET /api/user/dashboard/ HTTP/1.1" 200 639
"GET /api/payments/history/ HTTP/1.1" 200 2
"GET /api/packages/ HTTP/1.1" 200 849
"GET /api/payments/history/ HTTP/1.1" 200 2
"GET /api/user/dashboard/ HTTP/1.1" 200 639
Not Found: /api/auth/logout/
"POST /api/auth/logout/ HTTP/1.1" 404 6037
Not Found: /api/auth/logout/
"POST /api/auth/logout/ HTTP/1.1" 404 6037
Not Found: /api/auth/logout/
"POST /api/auth/logout/ HTTP/1.1" 404 6037
"OPTIONS /api/auth/login/ HTTP/1.1" 200 0
"POST /api/auth/login/ HTTP/1.1" 200 1066
"GET /api/payments/history/ HTTP/1.1" 200 2
"GET /api/packages/ HTTP/1.1" 200 849
"GET /api/user/dashboard/ HTTP/1.1" 200 639
"GET /api/payments/history/ HTTP/1.1" 200 2
"GET /api/packages/ HTTP/1.1" 200 849
"GET /api/user/dashboard/ HTTP/1.1" 200 639
"GET /api/packages/ HTTP/1.1" 200 849
"GET /api/payments/history/ HTTP/1.1" 200 2
"GET /api/user/dashboard/ HTTP/1.1" 200 639
"GET /api/packages/ HTTP/1.1" 200 849
"GET /api/payments/history/ HTTP/1.1" 200 2
"GET /api/user/dashboard/ HTTP/1.1" 200 639
"OPTIONS /api/user/profile/ HTTP/1.1" 200 0
"OPTIONS /api/user/profile/ HTTP/1.1" 200 0
"GET /api/user/profile/ HTTP/1.1" 200 535
"GET /api/user/profile/ HTTP/1.1" 200 535
"GET /api/packages/ HTTP/1.1" 200 849
"GET /api/payments/history/ HTTP/1.1" 200 2
"GET /api/user/dashboard/ HTTP/1.1" 200 639
"GET /api/packages/ HTTP/1.1" 200 849
"GET /api/payments/history/ HTTP/1.1" 200 2
"GET /api/user/dashboard/ HTTP/1.1" 200 639
"OPTIONS /api/packages/upgrade/ HTTP/1.1" 200 0
"POST /api/packages/upgrade/ HTTP/1.1" 200 480
"OPTIONS /api/payments/confirm/ HTTP/1.1" 200 0
"POST /api/payments/confirm/ HTTP/1.1" 200 836
"GET /api/packages/ HTTP/1.1" 200 849
"GET /api/user/dashboard/ HTTP/1.1" 200 640
"GET /api/payments/history/ HTTP/1.1" 200 227
"POST /api/packages/upgrade/ HTTP/1.1" 200 480
"POST /api/payments/confirm/ HTTP/1.1" 200 836
"GET /api/packages/ HTTP/1.1" 200 849
"GET /api/user/dashboard/ HTTP/1.1" 200 641
"GET /api/payments/history/ HTTP/1.1" 200 453
"GET /api/packages/ HTTP/1.1" 200 849
"GET /api/user/dashboard/ HTTP/1.1" 200 641
"GET /api/payments/history/ HTTP/1.1" 200 453
"GET /api/user/profile/ HTTP/1.1" 200 534
"GET /api/user/profile/ HTTP/1.1" 200 534
"GET /api/packages/ HTTP/1.1" 200 849
"GET /api/user/dashboard/ HTTP/1.1" 200 641
"GET /api/payments/history/ HTTP/1.1" 200 453
"GET /api/packages/ HTTP/1.1" 200 849
"GET /api/user/dashboard/ HTTP/1.1" 200 641
"GET /api/payments/history/ HTTP/1.1" 200 453
"GET /api/user/profile/ HTTP/1.1" 200 534
"GET /api/user/profile/ HTTP/1.1" 200 534
"GET /api/user/profile/ HTTP/1.1" 200 534
"GET /api/user/profile/ HTTP/1.1" 200 534
"OPTIONS /api/auth/register/ HTTP/1.1" 200 0
Bad Request: /api/auth/register/
"POST /api/auth/register/ HTTP/1.1" 400 112
Bad Request: /api/auth/register/
"POST /api/auth/register/ HTTP/1.1" 400 112
"POST /api/auth/register/ HTTP/1.1" 201 1085
"OPTIONS /api/user/dashboard/ HTTP/1.1" 200 0
"OPTIONS /api/packages/ HTTP/1.1" 200 0
"OPTIONS /api/user/dashboard/ HTTP/1.1" 200 0
"OPTIONS /api/payments/history/ HTTP/1.1" 200 0
"OPTIONS /api/packages/ HTTP/1.1" 200 0
"OPTIONS /api/payments/history/ HTTP/1.1" 200 0
"GET /api/packages/ HTTP/1.1" 200 849
"GET /api/payments/history/ HTTP/1.1" 200 2
"GET /api/user/dashboard/ HTTP/1.1" 200 646
"GET /api/packages/ HTTP/1.1" 200 849
"GET /api/payments/history/ HTTP/1.1" 200 2
"GET /api/user/dashboard/ HTTP/1.1" 200 646
"OPTIONS /api/user/profile/ HTTP/1.1" 200 0
"GET /api/user/profile/ HTTP/1.1" 200 542
"GET /api/user/profile/ HTTP/1.1" 200 542
"GET /api/packages/ HTTP/1.1" 200 849
"GET /api/payments/history/ HTTP/1.1" 200 2
"GET /api/user/dashboard/ HTTP/1.1" 200 646
"GET /api/packages/ HTTP/1.1" 200 849
"GET /api/payments/history/ HTTP/1.1" 200 2
"GET /api/user/dashboard/ HTTP/1.1" 200 646
"GET /api/user/profile/ HTTP/1.1" 200 542
"GET /api/user/profile/ HTTP/1.1" 200 542
"OPTIONS /api/user/profile/ HTTP/1.1" 200 0
"OPTIONS /api/user/profile/ HTTP/1.1" 200 0
Unauthorized: /api/user/profile/
"GET /api/user/profile/ HTTP/1.1" 401 172
Unauthorized: /api/user/profile/
"GET /api/user/profile/ HTTP/1.1" 401 172
"OPTIONS /api/token/refresh/ HTTP/1.1" 200 0
"OPTIONS /api/token/refresh/ HTTP/1.1" 200 0
Internal Server Error: /api/token/refresh/
Traceback (most recent call last):
  File "C:\Users\user\Documents\react-tailwind\Lib\site-packages\django\core\handlers\exception.py", line 55, in inner
    response = get_response(request)
               ^^^^^^^^^^^^^^^^^^^^^
  File "C:\Users\user\Documents\react-tailwind\Lib\site-packages\django\core\handlers\base.py", line 197, in _get_response
    response = wrapped_callback(request, *callback_args, **callback_kwargs)
               ^^^^^^^^^^^^^^^^^^^^^^^^^^^^^^^^^^^^^^^^^^^^^^^^^^^^^^^^^^^^
  File "C:\Users\user\Documents\react-tailwind\Lib\site-packages\django\views\decorators\csrf.py", line 65, in _view_wrapper
    return view_func(request, *args, **kwargs)
           ^^^^^^^^^^^^^^^^^^^^^^^^^^^^^^^^^^^
  File "C:\Users\user\Documents\react-tailwind\Lib\site-packages\django\views\generic\base.py", line 104, in view
    return self.dispatch(request, *args, **kwargs)
           ^^^^^^^^^^^^^^^^^^^^^^^^^^^^^^^^^^^^^^^
  File "C:\Users\user\Documents\react-tailwind\Lib\site-packages\rest_framework\views.py", line 509, in dispatch
    response = self.handle_exception(exc)
               ^^^^^^^^^^^^^^^^^^^^^^^^^^
  File "C:\Users\user\Documents\react-tailwind\Lib\site-packages\rest_framework\views.py", line 469, in handle_exception
    self.raise_uncaught_exception(exc)
  File "C:\Users\user\Documents\react-tailwind\Lib\site-packages\rest_framework\views.py", line 480, in raise_uncaught_exception
    raise exc
  File "C:\Users\user\Documents\react-tailwind\Lib\site-packages\rest_framework\views.py", line 506, in dispatch
    response = handler(request, *args, **kwargs)
               ^^^^^^^^^^^^^^^^^^^^^^^^^^^^^^^^^
  File "C:\Users\user\Documents\react-tailwind\Lib\site-packages\rest_framework_simplejwt\views.py", line 44, in post
    serializer.is_valid(raise_exception=True)
  File "C:\Users\user\Documents\react-tailwind\Lib\site-packages\rest_framework\serializers.py", line 223, in is_valid
    self._validated_data = self.run_validation(self.initial_data)
                           ^^^^^^^^^^^^^^^^^^^^^^^^^^^^^^^^^^^^^^
  File "C:\Users\user\Documents\react-tailwind\Lib\site-packages\rest_framework\serializers.py", line 445, in run_validation
    value = self.validate(value)
            ^^^^^^^^^^^^^^^^^^^^
  File "C:\Users\user\Documents\react-tailwind\Lib\site-packages\rest_framework_simplejwt\serializers.py", line 141, in validate
    refresh.outstand()
  File "C:\Users\user\Documents\react-tailwind\Lib\site-packages\rest_framework_simplejwt\tokens.py", line 222, in outstand
    return OutstandingToken.objects.get_or_create(
           ^^^^^^^^^^^^^^^^^^^^^^^^
AttributeError: type object 'OutstandingToken' has no attribute 'objects'
Internal Server Error: /api/token/refresh/
Traceback (most recent call last):
  File "C:\Users\user\Documents\react-tailwind\Lib\site-packages\django\core\handlers\exception.py", line 55, in inner
    response = get_response(request)
               ^^^^^^^^^^^^^^^^^^^^^
  File "C:\Users\user\Documents\react-tailwind\Lib\site-packages\django\core\handlers\base.py", line 197, in _get_response
    response = wrapped_callback(request, *callback_args, **callback_kwargs)
               ^^^^^^^^^^^^^^^^^^^^^^^^^^^^^^^^^^^^^^^^^^^^^^^^^^^^^^^^^^^^
  File "C:\Users\user\Documents\react-tailwind\Lib\site-packages\django\views\decorators\csrf.py", line 65, in _view_wrapper
    return view_func(request, *args, **kwargs)
           ^^^^^^^^^^^^^^^^^^^^^^^^^^^^^^^^^^^
  File "C:\Users\user\Documents\react-tailwind\Lib\site-packages\django\views\generic\base.py", line 104, in view
    return self.dispatch(request, *args, **kwargs)
           ^^^^^^^^^^^^^^^^^^^^^^^^^^^^^^^^^^^^^^^
  File "C:\Users\user\Documents\react-tailwind\Lib\site-packages\rest_framework\views.py", line 509, in dispatch
    response = self.handle_exception(exc)
               ^^^^^^^^^^^^^^^^^^^^^^^^^^
  File "C:\Users\user\Documents\react-tailwind\Lib\site-packages\rest_framework\views.py", line 469, in handle_exception
    self.raise_uncaught_exception(exc)
  File "C:\Users\user\Documents\react-tailwind\Lib\site-packages\rest_framework\views.py", line 480, in raise_uncaught_exception
    raise exc
  File "C:\Users\user\Documents\react-tailwind\Lib\site-packages\rest_framework\views.py", line 506, in dispatch
    response = handler(request, *args, **kwargs)
               ^^^^^^^^^^^^^^^^^^^^^^^^^^^^^^^^^
  File "C:\Users\user\Documents\react-tailwind\Lib\site-packages\rest_framework_simplejwt\views.py", line 44, in post
    serializer.is_valid(raise_exception=True)
  File "C:\Users\user\Documents\react-tailwind\Lib\site-packages\rest_framework\serializers.py", line 223, in is_valid
    self._validated_data = self.run_validation(self.initial_data)
                           ^^^^^^^^^^^^^^^^^^^^^^^^^^^^^^^^^^^^^^
  File "C:\Users\user\Documents\react-tailwind\Lib\site-packages\rest_framework\serializers.py", line 445, in run_validation
    value = self.validate(value)
            ^^^^^^^^^^^^^^^^^^^^
  File "C:\Users\user\Documents\react-tailwind\Lib\site-packages\rest_framework_simplejwt\serializers.py", line 141, in validate
    refresh.outstand()
  File "C:\Users\user\Documents\react-tailwind\Lib\site-packages\rest_framework_simplejwt\tokens.py", line 222, in outstand
    return OutstandingToken.objects.get_or_create(
           ^^^^^^^^^^^^^^^^^^^^^^^^
AttributeError: type object 'OutstandingToken' has no attribute 'objects'
"POST /api/token/refresh/ HTTP/1.1" 500 120915
"POST /api/token/refresh/ HTTP/1.1" 500 120915
"OPTIONS /api/user/profile/ HTTP/1.1" 200 0
"OPTIONS /api/user/profile/ HTTP/1.1" 200 0
Unauthorized: /api/user/profile/
"GET /api/user/profile/ HTTP/1.1" 401 172
Unauthorized: /api/user/profile/
"GET /api/user/profile/ HTTP/1.1" 401 172
"OPTIONS /api/token/refresh/ HTTP/1.1" 200 0
"OPTIONS /api/token/refresh/ HTTP/1.1" 200 0
Internal Server Error: /api/token/refresh/
Traceback (most recent call last):
  File "C:\Users\user\Documents\react-tailwind\Lib\site-packages\django\core\handlers\exception.py", line 55, in inner
    response = get_response(request)
               ^^^^^^^^^^^^^^^^^^^^^
  File "C:\Users\user\Documents\react-tailwind\Lib\site-packages\django\core\handlers\base.py", line 197, in _get_response
    response = wrapped_callback(request, *callback_args, **callback_kwargs)
               ^^^^^^^^^^^^^^^^^^^^^^^^^^^^^^^^^^^^^^^^^^^^^^^^^^^^^^^^^^^^
  File "C:\Users\user\Documents\react-tailwind\Lib\site-packages\django\views\decorators\csrf.py", line 65, in _view_wrapper
    return view_func(request, *args, **kwargs)
           ^^^^^^^^^^^^^^^^^^^^^^^^^^^^^^^^^^^
  File "C:\Users\user\Documents\react-tailwind\Lib\site-packages\django\views\generic\base.py", line 104, in view
    return self.dispatch(request, *args, **kwargs)
           ^^^^^^^^^^^^^^^^^^^^^^^^^^^^^^^^^^^^^^^
  File "C:\Users\user\Documents\react-tailwind\Lib\site-packages\rest_framework\views.py", line 509, in dispatch
    response = self.handle_exception(exc)
               ^^^^^^^^^^^^^^^^^^^^^^^^^^
  File "C:\Users\user\Documents\react-tailwind\Lib\site-packages\rest_framework\views.py", line 469, in handle_exception
    self.raise_uncaught_exception(exc)
  File "C:\Users\user\Documents\react-tailwind\Lib\site-packages\rest_framework\views.py", line 480, in raise_uncaught_exception
    raise exc
  File "C:\Users\user\Documents\react-tailwind\Lib\site-packages\rest_framework\views.py", line 506, in dispatch
    response = handler(request, *args, **kwargs)
               ^^^^^^^^^^^^^^^^^^^^^^^^^^^^^^^^^
  File "C:\Users\user\Documents\react-tailwind\Lib\site-packages\rest_framework_simplejwt\views.py", line 44, in post
    serializer.is_valid(raise_exception=True)
  File "C:\Users\user\Documents\react-tailwind\Lib\site-packages\rest_framework\serializers.py", line 223, in is_valid
    self._validated_data = self.run_validation(self.initial_data)
                           ^^^^^^^^^^^^^^^^^^^^^^^^^^^^^^^^^^^^^^
  File "C:\Users\user\Documents\react-tailwind\Lib\site-packages\rest_framework\serializers.py", line 445, in run_validation
    value = self.validate(value)
            ^^^^^^^^^^^^^^^^^^^^
  File "C:\Users\user\Documents\react-tailwind\Lib\site-packages\rest_framework_simplejwt\serializers.py", line 141, in validate
    refresh.outstand()
  File "C:\Users\user\Documents\react-tailwind\Lib\site-packages\rest_framework_simplejwt\tokens.py", line 222, in outstand
    return OutstandingToken.objects.get_or_create(
           ^^^^^^^^^^^^^^^^^^^^^^^^
AttributeError: type object 'OutstandingToken' has no attribute 'objects'
Internal Server Error: /api/token/refresh/
Traceback (most recent call last):
  File "C:\Users\user\Documents\react-tailwind\Lib\site-packages\django\core\handlers\exception.py", line 55, in inner
    response = get_response(request)
               ^^^^^^^^^^^^^^^^^^^^^
  File "C:\Users\user\Documents\react-tailwind\Lib\site-packages\django\core\handlers\base.py", line 197, in _get_response
    response = wrapped_callback(request, *callback_args, **callback_kwargs)
               ^^^^^^^^^^^^^^^^^^^^^^^^^^^^^^^^^^^^^^^^^^^^^^^^^^^^^^^^^^^^
  File "C:\Users\user\Documents\react-tailwind\Lib\site-packages\django\views\decorators\csrf.py", line 65, in _view_wrapper
    return view_func(request, *args, **kwargs)
           ^^^^^^^^^^^^^^^^^^^^^^^^^^^^^^^^^^^
  File "C:\Users\user\Documents\react-tailwind\Lib\site-packages\django\views\generic\base.py", line 104, in view
    return self.dispatch(request, *args, **kwargs)
           ^^^^^^^^^^^^^^^^^^^^^^^^^^^^^^^^^^^^^^^
  File "C:\Users\user\Documents\react-tailwind\Lib\site-packages\rest_framework\views.py", line 509, in dispatch
    response = self.handle_exception(exc)
               ^^^^^^^^^^^^^^^^^^^^^^^^^^
  File "C:\Users\user\Documents\react-tailwind\Lib\site-packages\rest_framework\views.py", line 469, in handle_exception
    self.raise_uncaught_exception(exc)
  File "C:\Users\user\Documents\react-tailwind\Lib\site-packages\rest_framework\views.py", line 480, in raise_uncaught_exception
    raise exc
  File "C:\Users\user\Documents\react-tailwind\Lib\site-packages\rest_framework\views.py", line 506, in dispatch
    response = handler(request, *args, **kwargs)
               ^^^^^^^^^^^^^^^^^^^^^^^^^^^^^^^^^
  File "C:\Users\user\Documents\react-tailwind\Lib\site-packages\rest_framework_simplejwt\views.py", line 44, in post
    serializer.is_valid(raise_exception=True)
  File "C:\Users\user\Documents\react-tailwind\Lib\site-packages\rest_framework\serializers.py", line 223, in is_valid
    self._validated_data = self.run_validation(self.initial_data)
                           ^^^^^^^^^^^^^^^^^^^^^^^^^^^^^^^^^^^^^^
  File "C:\Users\user\Documents\react-tailwind\Lib\site-packages\rest_framework\serializers.py", line 445, in run_validation
    value = self.validate(value)
            ^^^^^^^^^^^^^^^^^^^^
  File "C:\Users\user\Documents\react-tailwind\Lib\site-packages\rest_framework_simplejwt\serializers.py", line 141, in validate
    refresh.outstand()
  File "C:\Users\user\Documents\react-tailwind\Lib\site-packages\rest_framework_simplejwt\tokens.py", line 222, in outstand
    return OutstandingToken.objects.get_or_create(
           ^^^^^^^^^^^^^^^^^^^^^^^^
AttributeError: type object 'OutstandingToken' has no attribute 'objects'
"POST /api/token/refresh/ HTTP/1.1" 500 120933
"POST /api/token/refresh/ HTTP/1.1" 500 120933
"OPTIONS /api/auth/login/ HTTP/1.1" 200 0
"POST /api/auth/login/ HTTP/1.1" 200 1065
"OPTIONS /api/user/dashboard/ HTTP/1.1" 200 0
"OPTIONS /api/packages/ HTTP/1.1" 200 0
"OPTIONS /api/payments/history/ HTTP/1.1" 200 0
"OPTIONS /api/user/dashboard/ HTTP/1.1" 200 0
"OPTIONS /api/packages/ HTTP/1.1" 200 0
"OPTIONS /api/payments/history/ HTTP/1.1" 200 0
"GET /api/packages/ HTTP/1.1" 200 849
"GET /api/user/dashboard/ HTTP/1.1" 200 641
"GET /api/payments/history/ HTTP/1.1" 200 453
"OPTIONS /api/auth/logout/ HTTP/1.1" 200 0
Not Found: /api/auth/logout/
"POST /api/auth/logout/ HTTP/1.1" 404 6037
"GET /api/packages/ HTTP/1.1" 200 849
"GET /api/payments/history/ HTTP/1.1" 200 453
"GET /api/user/dashboard/ HTTP/1.1" 200 641
"POST /api/auth/login/ HTTP/1.1" 200 1065
"GET /api/packages/ HTTP/1.1" 200 849
"GET /api/user/dashboard/ HTTP/1.1" 200 641
"GET /api/payments/history/ HTTP/1.1" 200 453
"GET /api/packages/ HTTP/1.1" 200 849
"GET /api/user/dashboard/ HTTP/1.1" 200 641
"GET /api/payments/history/ HTTP/1.1" 200 453
"GET /api/user/profile/ HTTP/1.1" 200 534
"GET /api/user/profile/ HTTP/1.1" 200 534
"GET /api/user/profile/ HTTP/1.1" 200 534
"GET /api/user/profile/ HTTP/1.1" 200 534
"GET /api/user/profile/ HTTP/1.1" 200 534
- Broken pipe from ('127.0.0.1', 53612)
"GET /api/user/profile/ HTTP/1.1" 200 534
- Broken pipe from ('127.0.0.1', 53614)
- Broken pipe from ('127.0.0.1', 53624)
"GET /api/user/profile/ HTTP/1.1" 200 534
"GET /api/user/profile/ HTTP/1.1" 200 534
"GET /api/user/profile/ HTTP/1.1" 200 534
"GET /api/user/profile/ HTTP/1.1" 200 534
- Broken pipe from ('127.0.0.1', 53625)
"GET /api/user/profile/ HTTP/1.1" 200 534
"GET /api/user/profile/ HTTP/1.1" 200 534
"GET /api/user/profile/ HTTP/1.1" 200 534
"GET /api/user/profile/ HTTP/1.1" 200 534
"GET /api/user/profile/ HTTP/1.1" 200 534
"GET /api/user/profile/ HTTP/1.1" 200 534
"GET /api/user/profile/ HTTP/1.1" 200 534
"GET /api/user/profile/ HTTP/1.1" 200 534
"GET /api/packages/ HTTP/1.1" 200 849
"GET /api/user/dashboard/ HTTP/1.1" 200 641
"GET /api/payments/history/ HTTP/1.1" 200 453
"GET /api/packages/ HTTP/1.1" 200 849
"GET /api/user/dashboard/ HTTP/1.1" 200 641
"GET /api/payments/history/ HTTP/1.1" 200 453
"GET /api/user/profile/ HTTP/1.1" 200 534
"GET /api/user/profile/ HTTP/1.1" 200 534
"GET /api/user/profile/ HTTP/1.1" 200 534
"GET /api/user/profile/ HTTP/1.1" 200 534
"GET /api/packages/ HTTP/1.1" 200 849
"GET /api/user/dashboard/ HTTP/1.1" 200 641
"GET /api/payments/history/ HTTP/1.1" 200 453
"GET /api/packages/ HTTP/1.1" 200 849
"GET /api/user/dashboard/ HTTP/1.1" 200 641
"GET /api/payments/history/ HTTP/1.1" 200 453
Not Found: /api/auth/logout/
"POST /api/auth/logout/ HTTP/1.1" 404 6037
"POST /api/auth/login/ HTTP/1.1" 200 1065
"GET /api/packages/ HTTP/1.1" 200 849
"GET /api/payments/history/ HTTP/1.1" 200 453
"GET /api/packages/ HTTP/1.1" 200 849
"GET /api/user/dashboard/ HTTP/1.1" 200 641
"GET /api/payments/history/ HTTP/1.1" 200 453
"GET /api/user/dashboard/ HTTP/1.1" 200 641
"GET /api/user/profile/ HTTP/1.1" 200 534
"GET /api/user/profile/ HTTP/1.1" 200 534
"GET /api/user/profile/ HTTP/1.1" 200 534
"GET /api/user/profile/ HTTP/1.1" 200 534
Not Found: /api/auth/logout/
"POST /api/auth/logout/ HTTP/1.1" 404 6037
"POST /api/auth/login/ HTTP/1.1" 200 1065
"GET /api/packages/ HTTP/1.1" 200 849
"GET /api/user/dashboard/ HTTP/1.1" 200 641
"GET /api/payments/history/ HTTP/1.1" 200 453
"GET /api/packages/ HTTP/1.1" 200 849
"GET /api/user/dashboard/ HTTP/1.1" 200 641
"GET /api/payments/history/ HTTP/1.1" 200 453
"GET /api/user/profile/ HTTP/1.1" 200 534
"GET /api/user/profile/ HTTP/1.1" 200 534
"GET /api/user/profile/ HTTP/1.1" 200 534
"GET /api/user/profile/ HTTP/1.1" 200 534
Internal Server Error: /api/user/profile/
Traceback (most recent call last):
  File "C:\Users\user\Documents\react-tailwind\Lib\site-packages\django\db\backends\base\base.py", line 279, in ensure_connection
    self.connect()
  File "C:\Users\user\Documents\react-tailwind\Lib\site-packages\django\utils\asyncio.py", line 26, in inner
    return func(*args, **kwargs)
           ^^^^^^^^^^^^^^^^^^^^^
  File "C:\Users\user\Documents\react-tailwind\Lib\site-packages\django\db\backends\base\base.py", line 256, in connect
    self.connection = self.get_new_connection(conn_params)
                      ^^^^^^^^^^^^^^^^^^^^^^^^^^^^^^^^^^^^
  File "C:\Users\user\Documents\react-tailwind\Lib\site-packages\django\utils\asyncio.py", line 26, in inner
    return func(*args, **kwargs)
           ^^^^^^^^^^^^^^^^^^^^^
  File "C:\Users\user\Documents\react-tailwind\Lib\site-packages\django\db\backends\postgresql\base.py", line 332, in get_new_connection
    connection = self.Database.connect(**conn_params)
                 ^^^^^^^^^^^^^^^^^^^^^^^^^^^^^^^^^^^^
  File "C:\Users\user\Documents\react-tailwind\Lib\site-packages\psycopg2\__init__.py", line 122, in connect
    conn = _connect(dsn, connection_factory=connection_factory, **kwasync)
           ^^^^^^^^^^^^^^^^^^^^^^^^^^^^^^^^^^^^^^^^^^^^^^^^^^^^^^^^^^^^^^^
psycopg2.OperationalError: could not translate host name "postgresql-mtaa-wetu0.alwaysdata.net" to address: No such host is known. 


The above exception was the direct cause of the following exception:

Traceback (most recent call last):
  File "C:\Users\user\Documents\react-tailwind\Lib\site-packages\django\core\handlers\exception.py", line 55, in inner
    response = get_response(request)
               ^^^^^^^^^^^^^^^^^^^^^
  File "C:\Users\user\Documents\react-tailwind\Lib\site-packages\django\core\handlers\base.py", line 197, in _get_response
    response = wrapped_callback(request, *callback_args, **callback_kwargs)
               ^^^^^^^^^^^^^^^^^^^^^^^^^^^^^^^^^^^^^^^^^^^^^^^^^^^^^^^^^^^^
  File "C:\Users\user\Documents\react-tailwind\Lib\site-packages\django\views\decorators\csrf.py", line 65, in _view_wrapper
    return view_func(request, *args, **kwargs)
           ^^^^^^^^^^^^^^^^^^^^^^^^^^^^^^^^^^^
  File "C:\Users\user\Documents\react-tailwind\Lib\site-packages\django\views\generic\base.py", line 104, in view
    return self.dispatch(request, *args, **kwargs)
           ^^^^^^^^^^^^^^^^^^^^^^^^^^^^^^^^^^^^^^^
  File "C:\Users\user\Documents\react-tailwind\Lib\site-packages\rest_framework\views.py", line 509, in dispatch
    response = self.handle_exception(exc)
               ^^^^^^^^^^^^^^^^^^^^^^^^^^
  File "C:\Users\user\Documents\react-tailwind\Lib\site-packages\rest_framework\views.py", line 469, in handle_exception
    self.raise_uncaught_exception(exc)
  File "C:\Users\user\Documents\react-tailwind\Lib\site-packages\rest_framework\views.py", line 480, in raise_uncaught_exception
    raise exc
  File "C:\Users\user\Documents\react-tailwind\Lib\site-packages\rest_framework\views.py", line 497, in dispatch
    self.initial(request, *args, **kwargs)
  File "C:\Users\user\Documents\react-tailwind\Lib\site-packages\rest_framework\views.py", line 414, in initial
    self.perform_authentication(request)
  File "C:\Users\user\Documents\react-tailwind\Lib\site-packages\rest_framework\views.py", line 324, in perform_authentication
    request.user
  File "C:\Users\user\Documents\react-tailwind\Lib\site-packages\rest_framework\request.py", line 231, in user
    self._authenticate()
  File "C:\Users\user\Documents\react-tailwind\Lib\site-packages\rest_framework\request.py", line 384, in _authenticate
    user_auth_tuple = authenticator.authenticate(self)
                      ^^^^^^^^^^^^^^^^^^^^^^^^^^^^^^^^
  File "C:\Users\user\Documents\react-tailwind\Lib\site-packages\rest_framework_simplejwt\authentication.py", line 51, in authenticate
    return self.get_user(validated_token), validated_token
           ^^^^^^^^^^^^^^^^^^^^^^^^^^^^^^
  File "C:\Users\user\Documents\react-tailwind\Lib\site-packages\rest_framework_simplejwt\authentication.py", line 130, in get_user
    user = self.user_model.objects.get(**{api_settings.USER_ID_FIELD: user_id})
           ^^^^^^^^^^^^^^^^^^^^^^^^^^^^^^^^^^^^^^^^^^^^^^^^^^^^^^^^^^^^^^^^^^^^
  File "C:\Users\user\Documents\react-tailwind\Lib\site-packages\django\db\models\manager.py", line 87, in manager_method
    return getattr(self.get_queryset(), name)(*args, **kwargs)
           ^^^^^^^^^^^^^^^^^^^^^^^^^^^^^^^^^^^^^^^^^^^^^^^^^^^
  File "C:\Users\user\Documents\react-tailwind\Lib\site-packages\django\db\models\query.py", line 645, in get
    num = len(clone)
          ^^^^^^^^^^
  File "C:\Users\user\Documents\react-tailwind\Lib\site-packages\django\db\models\query.py", line 382, in __len__
    self._fetch_all()
  File "C:\Users\user\Documents\react-tailwind\Lib\site-packages\django\db\models\query.py", line 1928, in _fetch_all
    self._result_cache = list(self._iterable_class(self))
                         ^^^^^^^^^^^^^^^^^^^^^^^^^^^^^^^^
  File "C:\Users\user\Documents\react-tailwind\Lib\site-packages\django\db\models\query.py", line 91, in __iter__
    results = compiler.execute_sql(
              ^^^^^^^^^^^^^^^^^^^^^
  File "C:\Users\user\Documents\react-tailwind\Lib\site-packages\django\db\models\sql\compiler.py", line 1572, in execute_sql
    cursor = self.connection.cursor()
             ^^^^^^^^^^^^^^^^^^^^^^^^
  File "C:\Users\user\Documents\react-tailwind\Lib\site-packages\django\utils\asyncio.py", line 26, in inner
    return func(*args, **kwargs)
           ^^^^^^^^^^^^^^^^^^^^^
  File "C:\Users\user\Documents\react-tailwind\Lib\site-packages\django\db\backends\base\base.py", line 320, in cursor
    return self._cursor()
           ^^^^^^^^^^^^^^
  File "C:\Users\user\Documents\react-tailwind\Lib\site-packages\django\db\backends\base\base.py", line 296, in _cursor
    self.ensure_connection()
  File "C:\Users\user\Documents\react-tailwind\Lib\site-packages\django\utils\asyncio.py", line 26, in inner
    return func(*args, **kwargs)
           ^^^^^^^^^^^^^^^^^^^^^
  File "C:\Users\user\Documents\react-tailwind\Lib\site-packages\django\db\backends\base\base.py", line 278, in ensure_connection
    with self.wrap_database_errors:
         ^^^^^^^^^^^^^^^^^^^^^^^^^
  File "C:\Users\user\Documents\react-tailwind\Lib\site-packages\django\db\utils.py", line 91, in __exit__
    raise dj_exc_value.with_traceback(traceback) from exc_value
  File "C:\Users\user\Documents\react-tailwind\Lib\site-packages\django\db\backends\base\base.py", line 279, in ensure_connection
    self.connect()
  File "C:\Users\user\Documents\react-tailwind\Lib\site-packages\django\utils\asyncio.py", line 26, in inner
    return func(*args, **kwargs)
           ^^^^^^^^^^^^^^^^^^^^^
  File "C:\Users\user\Documents\react-tailwind\Lib\site-packages\django\db\backends\base\base.py", line 256, in connect
    self.connection = self.get_new_connection(conn_params)
                      ^^^^^^^^^^^^^^^^^^^^^^^^^^^^^^^^^^^^
  File "C:\Users\user\Documents\react-tailwind\Lib\site-packages\django\utils\asyncio.py", line 26, in inner
    return func(*args, **kwargs)
           ^^^^^^^^^^^^^^^^^^^^^
  File "C:\Users\user\Documents\react-tailwind\Lib\site-packages\django\db\backends\postgresql\base.py", line 332, in get_new_connection
    connection = self.Database.connect(**conn_params)
                 ^^^^^^^^^^^^^^^^^^^^^^^^^^^^^^^^^^^^
  File "C:\Users\user\Documents\react-tailwind\Lib\site-packages\psycopg2\__init__.py", line 122, in connect
    conn = _connect(dsn, connection_factory=connection_factory, **kwasync)
           ^^^^^^^^^^^^^^^^^^^^^^^^^^^^^^^^^^^^^^^^^^^^^^^^^^^^^^^^^^^^^^^
django.db.utils.OperationalError: could not translate host name "postgresql-mtaa-wetu0.alwaysdata.net" to address: No such host is known. 

"GET /api/user/profile/ HTTP/1.1" 500 228549
Internal Server Error: /api/token/refresh/
Traceback (most recent call last):
  File "C:\Users\user\Documents\react-tailwind\Lib\site-packages\django\db\backends\base\base.py", line 279, in ensure_connection
    self.connect()
  File "C:\Users\user\Documents\react-tailwind\Lib\site-packages\django\utils\asyncio.py", line 26, in inner
    return func(*args, **kwargs)
           ^^^^^^^^^^^^^^^^^^^^^
  File "C:\Users\user\Documents\react-tailwind\Lib\site-packages\django\db\backends\base\base.py", line 256, in connect
    self.connection = self.get_new_connection(conn_params)
                      ^^^^^^^^^^^^^^^^^^^^^^^^^^^^^^^^^^^^
  File "C:\Users\user\Documents\react-tailwind\Lib\site-packages\django\utils\asyncio.py", line 26, in inner
    return func(*args, **kwargs)
           ^^^^^^^^^^^^^^^^^^^^^
  File "C:\Users\user\Documents\react-tailwind\Lib\site-packages\django\db\backends\postgresql\base.py", line 332, in get_new_connection
    connection = self.Database.connect(**conn_params)
                 ^^^^^^^^^^^^^^^^^^^^^^^^^^^^^^^^^^^^
  File "C:\Users\user\Documents\react-tailwind\Lib\site-packages\psycopg2\__init__.py", line 122, in connect
    conn = _connect(dsn, connection_factory=connection_factory, **kwasync)
           ^^^^^^^^^^^^^^^^^^^^^^^^^^^^^^^^^^^^^^^^^^^^^^^^^^^^^^^^^^^^^^^
psycopg2.OperationalError: could not translate host name "postgresql-mtaa-wetu0.alwaysdata.net" to address: No such host is known. 


The above exception was the direct cause of the following exception:

Traceback (most recent call last):
  File "C:\Users\user\Documents\react-tailwind\Lib\site-packages\django\core\handlers\exception.py", line 55, in inner
    response = get_response(request)
               ^^^^^^^^^^^^^^^^^^^^^
  File "C:\Users\user\Documents\react-tailwind\Lib\site-packages\django\core\handlers\base.py", line 197, in _get_response
    response = wrapped_callback(request, *callback_args, **callback_kwargs)
               ^^^^^^^^^^^^^^^^^^^^^^^^^^^^^^^^^^^^^^^^^^^^^^^^^^^^^^^^^^^^
  File "C:\Users\user\Documents\react-tailwind\Lib\site-packages\django\views\decorators\csrf.py", line 65, in _view_wrapper
    return view_func(request, *args, **kwargs)
           ^^^^^^^^^^^^^^^^^^^^^^^^^^^^^^^^^^^
  File "C:\Users\user\Documents\react-tailwind\Lib\site-packages\django\views\generic\base.py", line 104, in view
    return self.dispatch(request, *args, **kwargs)
           ^^^^^^^^^^^^^^^^^^^^^^^^^^^^^^^^^^^^^^^
  File "C:\Users\user\Documents\react-tailwind\Lib\site-packages\rest_framework\views.py", line 509, in dispatch
    response = self.handle_exception(exc)
               ^^^^^^^^^^^^^^^^^^^^^^^^^^
  File "C:\Users\user\Documents\react-tailwind\Lib\site-packages\rest_framework\views.py", line 469, in handle_exception
    self.raise_uncaught_exception(exc)
  File "C:\Users\user\Documents\react-tailwind\Lib\site-packages\rest_framework\views.py", line 480, in raise_uncaught_exception
    raise exc
  File "C:\Users\user\Documents\react-tailwind\Lib\site-packages\rest_framework\views.py", line 506, in dispatch
    response = handler(request, *args, **kwargs)
               ^^^^^^^^^^^^^^^^^^^^^^^^^^^^^^^^^
  File "C:\Users\user\Documents\react-tailwind\Lib\site-packages\rest_framework_simplejwt\views.py", line 44, in post
    serializer.is_valid(raise_exception=True)
  File "C:\Users\user\Documents\react-tailwind\Lib\site-packages\rest_framework\serializers.py", line 223, in is_valid
    self._validated_data = self.run_validation(self.initial_data)
                           ^^^^^^^^^^^^^^^^^^^^^^^^^^^^^^^^^^^^^^
  File "C:\Users\user\Documents\react-tailwind\Lib\site-packages\rest_framework\serializers.py", line 445, in run_validation
    value = self.validate(value)
            ^^^^^^^^^^^^^^^^^^^^
  File "C:\Users\user\Documents\react-tailwind\Lib\site-packages\rest_framework_simplejwt\serializers.py", line 116, in validate
    user := get_user_model().objects.get(
            ^^^^^^^^^^^^^^^^^^^^^^^^^^^^^
  File "C:\Users\user\Documents\react-tailwind\Lib\site-packages\django\db\models\manager.py", line 87, in manager_method
    return getattr(self.get_queryset(), name)(*args, **kwargs)
           ^^^^^^^^^^^^^^^^^^^^^^^^^^^^^^^^^^^^^^^^^^^^^^^^^^^
  File "C:\Users\user\Documents\react-tailwind\Lib\site-packages\django\db\models\query.py", line 645, in get
    num = len(clone)
          ^^^^^^^^^^
  File "C:\Users\user\Documents\react-tailwind\Lib\site-packages\django\db\models\query.py", line 382, in __len__
    self._fetch_all()
  File "C:\Users\user\Documents\react-tailwind\Lib\site-packages\django\db\models\query.py", line 1928, in _fetch_all
    self._result_cache = list(self._iterable_class(self))
                         ^^^^^^^^^^^^^^^^^^^^^^^^^^^^^^^^
  File "C:\Users\user\Documents\react-tailwind\Lib\site-packages\django\db\models\query.py", line 91, in __iter__
    results = compiler.execute_sql(
              ^^^^^^^^^^^^^^^^^^^^^
  File "C:\Users\user\Documents\react-tailwind\Lib\site-packages\django\db\models\sql\compiler.py", line 1572, in execute_sql
    cursor = self.connection.cursor()
             ^^^^^^^^^^^^^^^^^^^^^^^^
  File "C:\Users\user\Documents\react-tailwind\Lib\site-packages\django\utils\asyncio.py", line 26, in inner
    return func(*args, **kwargs)
           ^^^^^^^^^^^^^^^^^^^^^
  File "C:\Users\user\Documents\react-tailwind\Lib\site-packages\django\db\backends\base\base.py", line 320, in cursor
    return self._cursor()
           ^^^^^^^^^^^^^^
  File "C:\Users\user\Documents\react-tailwind\Lib\site-packages\django\db\backends\base\base.py", line 296, in _cursor
    self.ensure_connection()
  File "C:\Users\user\Documents\react-tailwind\Lib\site-packages\django\utils\asyncio.py", line 26, in inner
    return func(*args, **kwargs)
           ^^^^^^^^^^^^^^^^^^^^^
  File "C:\Users\user\Documents\react-tailwind\Lib\site-packages\django\db\backends\base\base.py", line 278, in ensure_connection
    with self.wrap_database_errors:
         ^^^^^^^^^^^^^^^^^^^^^^^^^
  File "C:\Users\user\Documents\react-tailwind\Lib\site-packages\django\db\utils.py", line 91, in __exit__
    raise dj_exc_value.with_traceback(traceback) from exc_value
  File "C:\Users\user\Documents\react-tailwind\Lib\site-packages\django\db\backends\base\base.py", line 279, in ensure_connection
    self.connect()
  File "C:\Users\user\Documents\react-tailwind\Lib\site-packages\django\utils\asyncio.py", line 26, in inner
    return func(*args, **kwargs)
           ^^^^^^^^^^^^^^^^^^^^^
  File "C:\Users\user\Documents\react-tailwind\Lib\site-packages\django\db\backends\base\base.py", line 256, in connect
    self.connection = self.get_new_connection(conn_params)
                      ^^^^^^^^^^^^^^^^^^^^^^^^^^^^^^^^^^^^
  File "C:\Users\user\Documents\react-tailwind\Lib\site-packages\django\utils\asyncio.py", line 26, in inner
    return func(*args, **kwargs)
           ^^^^^^^^^^^^^^^^^^^^^
  File "C:\Users\user\Documents\react-tailwind\Lib\site-packages\django\db\backends\postgresql\base.py", line 332, in get_new_connection
    connection = self.Database.connect(**conn_params)
                 ^^^^^^^^^^^^^^^^^^^^^^^^^^^^^^^^^^^^
  File "C:\Users\user\Documents\react-tailwind\Lib\site-packages\psycopg2\__init__.py", line 122, in connect
    conn = _connect(dsn, connection_factory=connection_factory, **kwasync)
           ^^^^^^^^^^^^^^^^^^^^^^^^^^^^^^^^^^^^^^^^^^^^^^^^^^^^^^^^^^^^^^^
django.db.utils.OperationalError: could not translate host name "postgresql-mtaa-wetu0.alwaysdata.net" to address: No such host is known. 

Internal Server Error: /api/user/profile/
Traceback (most recent call last):
  File "C:\Users\user\Documents\react-tailwind\Lib\site-packages\django\db\backends\base\base.py", line 279, in ensure_connection
    self.connect()
  File "C:\Users\user\Documents\react-tailwind\Lib\site-packages\django\utils\asyncio.py", line 26, in inner
    return func(*args, **kwargs)
           ^^^^^^^^^^^^^^^^^^^^^
  File "C:\Users\user\Documents\react-tailwind\Lib\site-packages\django\db\backends\base\base.py", line 256, in connect
    self.connection = self.get_new_connection(conn_params)
                      ^^^^^^^^^^^^^^^^^^^^^^^^^^^^^^^^^^^^
  File "C:\Users\user\Documents\react-tailwind\Lib\site-packages\django\utils\asyncio.py", line 26, in inner
    return func(*args, **kwargs)
           ^^^^^^^^^^^^^^^^^^^^^
  File "C:\Users\user\Documents\react-tailwind\Lib\site-packages\django\db\backends\postgresql\base.py", line 332, in get_new_connection
    connection = self.Database.connect(**conn_params)
                 ^^^^^^^^^^^^^^^^^^^^^^^^^^^^^^^^^^^^
  File "C:\Users\user\Documents\react-tailwind\Lib\site-packages\psycopg2\__init__.py", line 122, in connect
    conn = _connect(dsn, connection_factory=connection_factory, **kwasync)
           ^^^^^^^^^^^^^^^^^^^^^^^^^^^^^^^^^^^^^^^^^^^^^^^^^^^^^^^^^^^^^^^
psycopg2.OperationalError: could not translate host name "postgresql-mtaa-wetu0.alwaysdata.net" to address: No such host is known. 


The above exception was the direct cause of the following exception:

Traceback (most recent call last):
  File "C:\Users\user\Documents\react-tailwind\Lib\site-packages\django\core\handlers\exception.py", line 55, in inner
    response = get_response(request)
               ^^^^^^^^^^^^^^^^^^^^^
  File "C:\Users\user\Documents\react-tailwind\Lib\site-packages\django\core\handlers\base.py", line 197, in _get_response
    response = wrapped_callback(request, *callback_args, **callback_kwargs)
               ^^^^^^^^^^^^^^^^^^^^^^^^^^^^^^^^^^^^^^^^^^^^^^^^^^^^^^^^^^^^
  File "C:\Users\user\Documents\react-tailwind\Lib\site-packages\django\views\decorators\csrf.py", line 65, in _view_wrapper
    return view_func(request, *args, **kwargs)
           ^^^^^^^^^^^^^^^^^^^^^^^^^^^^^^^^^^^
  File "C:\Users\user\Documents\react-tailwind\Lib\site-packages\django\views\generic\base.py", line 104, in view
    return self.dispatch(request, *args, **kwargs)
           ^^^^^^^^^^^^^^^^^^^^^^^^^^^^^^^^^^^^^^^
  File "C:\Users\user\Documents\react-tailwind\Lib\site-packages\rest_framework\views.py", line 509, in dispatch
    response = self.handle_exception(exc)
               ^^^^^^^^^^^^^^^^^^^^^^^^^^
  File "C:\Users\user\Documents\react-tailwind\Lib\site-packages\rest_framework\views.py", line 469, in handle_exception
    self.raise_uncaught_exception(exc)
  File "C:\Users\user\Documents\react-tailwind\Lib\site-packages\rest_framework\views.py", line 480, in raise_uncaught_exception
    raise exc
  File "C:\Users\user\Documents\react-tailwind\Lib\site-packages\rest_framework\views.py", line 497, in dispatch
    self.initial(request, *args, **kwargs)
  File "C:\Users\user\Documents\react-tailwind\Lib\site-packages\rest_framework\views.py", line 414, in initial
    self.perform_authentication(request)
  File "C:\Users\user\Documents\react-tailwind\Lib\site-packages\rest_framework\views.py", line 324, in perform_authentication
    request.user
  File "C:\Users\user\Documents\react-tailwind\Lib\site-packages\rest_framework\request.py", line 231, in user
    self._authenticate()
  File "C:\Users\user\Documents\react-tailwind\Lib\site-packages\rest_framework\request.py", line 384, in _authenticate
    user_auth_tuple = authenticator.authenticate(self)
                      ^^^^^^^^^^^^^^^^^^^^^^^^^^^^^^^^
  File "C:\Users\user\Documents\react-tailwind\Lib\site-packages\rest_framework_simplejwt\authentication.py", line 51, in authenticate
    return self.get_user(validated_token), validated_token
           ^^^^^^^^^^^^^^^^^^^^^^^^^^^^^^
  File "C:\Users\user\Documents\react-tailwind\Lib\site-packages\rest_framework_simplejwt\authentication.py", line 130, in get_user
    user = self.user_model.objects.get(**{api_settings.USER_ID_FIELD: user_id})
           ^^^^^^^^^^^^^^^^^^^^^^^^^^^^^^^^^^^^^^^^^^^^^^^^^^^^^^^^^^^^^^^^^^^^
  File "C:\Users\user\Documents\react-tailwind\Lib\site-packages\django\db\models\manager.py", line 87, in manager_method
    return getattr(self.get_queryset(), name)(*args, **kwargs)
           ^^^^^^^^^^^^^^^^^^^^^^^^^^^^^^^^^^^^^^^^^^^^^^^^^^^
  File "C:\Users\user\Documents\react-tailwind\Lib\site-packages\django\db\models\query.py", line 645, in get
    num = len(clone)
          ^^^^^^^^^^
  File "C:\Users\user\Documents\react-tailwind\Lib\site-packages\django\db\models\query.py", line 382, in __len__
    self._fetch_all()
  File "C:\Users\user\Documents\react-tailwind\Lib\site-packages\django\db\models\query.py", line 1928, in _fetch_all
    self._result_cache = list(self._iterable_class(self))
                         ^^^^^^^^^^^^^^^^^^^^^^^^^^^^^^^^
  File "C:\Users\user\Documents\react-tailwind\Lib\site-packages\django\db\models\query.py", line 91, in __iter__
    results = compiler.execute_sql(
              ^^^^^^^^^^^^^^^^^^^^^
  File "C:\Users\user\Documents\react-tailwind\Lib\site-packages\django\db\models\sql\compiler.py", line 1572, in execute_sql
    cursor = self.connection.cursor()
             ^^^^^^^^^^^^^^^^^^^^^^^^
  File "C:\Users\user\Documents\react-tailwind\Lib\site-packages\django\utils\asyncio.py", line 26, in inner
    return func(*args, **kwargs)
           ^^^^^^^^^^^^^^^^^^^^^
  File "C:\Users\user\Documents\react-tailwind\Lib\site-packages\django\db\backends\base\base.py", line 320, in cursor
    return self._cursor()
           ^^^^^^^^^^^^^^
  File "C:\Users\user\Documents\react-tailwind\Lib\site-packages\django\db\backends\base\base.py", line 296, in _cursor
    self.ensure_connection()
  File "C:\Users\user\Documents\react-tailwind\Lib\site-packages\django\utils\asyncio.py", line 26, in inner
    return func(*args, **kwargs)
           ^^^^^^^^^^^^^^^^^^^^^
  File "C:\Users\user\Documents\react-tailwind\Lib\site-packages\django\db\backends\base\base.py", line 278, in ensure_connection
    with self.wrap_database_errors:
         ^^^^^^^^^^^^^^^^^^^^^^^^^
  File "C:\Users\user\Documents\react-tailwind\Lib\site-packages\django\db\utils.py", line 91, in __exit__
    raise dj_exc_value.with_traceback(traceback) from exc_value
  File "C:\Users\user\Documents\react-tailwind\Lib\site-packages\django\db\backends\base\base.py", line 279, in ensure_connection
    self.connect()
  File "C:\Users\user\Documents\react-tailwind\Lib\site-packages\django\utils\asyncio.py", line 26, in inner
    return func(*args, **kwargs)
           ^^^^^^^^^^^^^^^^^^^^^
  File "C:\Users\user\Documents\react-tailwind\Lib\site-packages\django\db\backends\base\base.py", line 256, in connect
    self.connection = self.get_new_connection(conn_params)
                      ^^^^^^^^^^^^^^^^^^^^^^^^^^^^^^^^^^^^
  File "C:\Users\user\Documents\react-tailwind\Lib\site-packages\django\utils\asyncio.py", line 26, in inner
    return func(*args, **kwargs)
           ^^^^^^^^^^^^^^^^^^^^^
  File "C:\Users\user\Documents\react-tailwind\Lib\site-packages\django\db\backends\postgresql\base.py", line 332, in get_new_connection
    connection = self.Database.connect(**conn_params)
                 ^^^^^^^^^^^^^^^^^^^^^^^^^^^^^^^^^^^^
  File "C:\Users\user\Documents\react-tailwind\Lib\site-packages\psycopg2\__init__.py", line 122, in connect
    conn = _connect(dsn, connection_factory=connection_factory, **kwasync)
           ^^^^^^^^^^^^^^^^^^^^^^^^^^^^^^^^^^^^^^^^^^^^^^^^^^^^^^^^^^^^^^^
django.db.utils.OperationalError: could not translate host name "postgresql-mtaa-wetu0.alwaysdata.net" to address: No such host is known. 

"POST /api/token/refresh/ HTTP/1.1" 500 222451
"GET /api/user/profile/ HTTP/1.1" 500 228549
Internal Server Error: /api/user/profile/
Traceback (most recent call last):
  File "C:\Users\user\Documents\react-tailwind\Lib\site-packages\django\db\backends\base\base.py", line 279, in ensure_connection
    self.connect()
  File "C:\Users\user\Documents\react-tailwind\Lib\site-packages\django\utils\asyncio.py", line 26, in inner
    return func(*args, **kwargs)
           ^^^^^^^^^^^^^^^^^^^^^
  File "C:\Users\user\Documents\react-tailwind\Lib\site-packages\django\db\backends\base\base.py", line 256, in connect
    self.connection = self.get_new_connection(conn_params)
                      ^^^^^^^^^^^^^^^^^^^^^^^^^^^^^^^^^^^^
  File "C:\Users\user\Documents\react-tailwind\Lib\site-packages\django\utils\asyncio.py", line 26, in inner
    return func(*args, **kwargs)
           ^^^^^^^^^^^^^^^^^^^^^
  File "C:\Users\user\Documents\react-tailwind\Lib\site-packages\django\db\backends\postgresql\base.py", line 332, in get_new_connection
    connection = self.Database.connect(**conn_params)
                 ^^^^^^^^^^^^^^^^^^^^^^^^^^^^^^^^^^^^
  File "C:\Users\user\Documents\react-tailwind\Lib\site-packages\psycopg2\__init__.py", line 122, in connect
    conn = _connect(dsn, connection_factory=connection_factory, **kwasync)
           ^^^^^^^^^^^^^^^^^^^^^^^^^^^^^^^^^^^^^^^^^^^^^^^^^^^^^^^^^^^^^^^
psycopg2.OperationalError: could not translate host name "postgresql-mtaa-wetu0.alwaysdata.net" to address: No such host is known. 


The above exception was the direct cause of the following exception:

Traceback (most recent call last):
  File "C:\Users\user\Documents\react-tailwind\Lib\site-packages\django\core\handlers\exception.py", line 55, in inner
    response = get_response(request)
               ^^^^^^^^^^^^^^^^^^^^^
  File "C:\Users\user\Documents\react-tailwind\Lib\site-packages\django\core\handlers\base.py", line 197, in _get_response
    response = wrapped_callback(request, *callback_args, **callback_kwargs)
               ^^^^^^^^^^^^^^^^^^^^^^^^^^^^^^^^^^^^^^^^^^^^^^^^^^^^^^^^^^^^
  File "C:\Users\user\Documents\react-tailwind\Lib\site-packages\django\views\decorators\csrf.py", line 65, in _view_wrapper
    return view_func(request, *args, **kwargs)
           ^^^^^^^^^^^^^^^^^^^^^^^^^^^^^^^^^^^
  File "C:\Users\user\Documents\react-tailwind\Lib\site-packages\django\views\generic\base.py", line 104, in view
    return self.dispatch(request, *args, **kwargs)
           ^^^^^^^^^^^^^^^^^^^^^^^^^^^^^^^^^^^^^^^
  File "C:\Users\user\Documents\react-tailwind\Lib\site-packages\rest_framework\views.py", line 509, in dispatch
    response = self.handle_exception(exc)
               ^^^^^^^^^^^^^^^^^^^^^^^^^^
  File "C:\Users\user\Documents\react-tailwind\Lib\site-packages\rest_framework\views.py", line 469, in handle_exception
    self.raise_uncaught_exception(exc)
  File "C:\Users\user\Documents\react-tailwind\Lib\site-packages\rest_framework\views.py", line 480, in raise_uncaught_exception
    raise exc
  File "C:\Users\user\Documents\react-tailwind\Lib\site-packages\rest_framework\views.py", line 497, in dispatch
    self.initial(request, *args, **kwargs)
  File "C:\Users\user\Documents\react-tailwind\Lib\site-packages\rest_framework\views.py", line 414, in initial
    self.perform_authentication(request)
  File "C:\Users\user\Documents\react-tailwind\Lib\site-packages\rest_framework\views.py", line 324, in perform_authentication
    request.user
  File "C:\Users\user\Documents\react-tailwind\Lib\site-packages\rest_framework\request.py", line 231, in user
    self._authenticate()
  File "C:\Users\user\Documents\react-tailwind\Lib\site-packages\rest_framework\request.py", line 384, in _authenticate
    user_auth_tuple = authenticator.authenticate(self)
                      ^^^^^^^^^^^^^^^^^^^^^^^^^^^^^^^^
  File "C:\Users\user\Documents\react-tailwind\Lib\site-packages\rest_framework_simplejwt\authentication.py", line 51, in authenticate
    return self.get_user(validated_token), validated_token
           ^^^^^^^^^^^^^^^^^^^^^^^^^^^^^^
  File "C:\Users\user\Documents\react-tailwind\Lib\site-packages\rest_framework_simplejwt\authentication.py", line 130, in get_user
    user = self.user_model.objects.get(**{api_settings.USER_ID_FIELD: user_id})
           ^^^^^^^^^^^^^^^^^^^^^^^^^^^^^^^^^^^^^^^^^^^^^^^^^^^^^^^^^^^^^^^^^^^^
  File "C:\Users\user\Documents\react-tailwind\Lib\site-packages\django\db\models\manager.py", line 87, in manager_method
    return getattr(self.get_queryset(), name)(*args, **kwargs)
           ^^^^^^^^^^^^^^^^^^^^^^^^^^^^^^^^^^^^^^^^^^^^^^^^^^^
  File "C:\Users\user\Documents\react-tailwind\Lib\site-packages\django\db\models\query.py", line 645, in get
    num = len(clone)
          ^^^^^^^^^^
  File "C:\Users\user\Documents\react-tailwind\Lib\site-packages\django\db\models\query.py", line 382, in __len__
    self._fetch_all()
  File "C:\Users\user\Documents\react-tailwind\Lib\site-packages\django\db\models\query.py", line 1928, in _fetch_all
    self._result_cache = list(self._iterable_class(self))
                         ^^^^^^^^^^^^^^^^^^^^^^^^^^^^^^^^
  File "C:\Users\user\Documents\react-tailwind\Lib\site-packages\django\db\models\query.py", line 91, in __iter__
    results = compiler.execute_sql(
              ^^^^^^^^^^^^^^^^^^^^^
  File "C:\Users\user\Documents\react-tailwind\Lib\site-packages\django\db\models\sql\compiler.py", line 1572, in execute_sql
    cursor = self.connection.cursor()
             ^^^^^^^^^^^^^^^^^^^^^^^^
  File "C:\Users\user\Documents\react-tailwind\Lib\site-packages\django\utils\asyncio.py", line 26, in inner
    return func(*args, **kwargs)
           ^^^^^^^^^^^^^^^^^^^^^
  File "C:\Users\user\Documents\react-tailwind\Lib\site-packages\django\db\backends\base\base.py", line 320, in cursor
    return self._cursor()
           ^^^^^^^^^^^^^^
  File "C:\Users\user\Documents\react-tailwind\Lib\site-packages\django\db\backends\base\base.py", line 296, in _cursor
    self.ensure_connection()
  File "C:\Users\user\Documents\react-tailwind\Lib\site-packages\django\utils\asyncio.py", line 26, in inner
    return func(*args, **kwargs)
           ^^^^^^^^^^^^^^^^^^^^^
  File "C:\Users\user\Documents\react-tailwind\Lib\site-packages\django\db\backends\base\base.py", line 278, in ensure_connection
    with self.wrap_database_errors:
         ^^^^^^^^^^^^^^^^^^^^^^^^^
  File "C:\Users\user\Documents\react-tailwind\Lib\site-packages\django\db\utils.py", line 91, in __exit__
    raise dj_exc_value.with_traceback(traceback) from exc_value
  File "C:\Users\user\Documents\react-tailwind\Lib\site-packages\django\db\backends\base\base.py", line 279, in ensure_connection
    self.connect()
  File "C:\Users\user\Documents\react-tailwind\Lib\site-packages\django\utils\asyncio.py", line 26, in inner
    return func(*args, **kwargs)
           ^^^^^^^^^^^^^^^^^^^^^
  File "C:\Users\user\Documents\react-tailwind\Lib\site-packages\django\db\backends\base\base.py", line 256, in connect
    self.connection = self.get_new_connection(conn_params)
                      ^^^^^^^^^^^^^^^^^^^^^^^^^^^^^^^^^^^^
  File "C:\Users\user\Documents\react-tailwind\Lib\site-packages\django\utils\asyncio.py", line 26, in inner
    return func(*args, **kwargs)
           ^^^^^^^^^^^^^^^^^^^^^
  File "C:\Users\user\Documents\react-tailwind\Lib\site-packages\django\db\backends\postgresql\base.py", line 332, in get_new_connection
    connection = self.Database.connect(**conn_params)
                 ^^^^^^^^^^^^^^^^^^^^^^^^^^^^^^^^^^^^
  File "C:\Users\user\Documents\react-tailwind\Lib\site-packages\psycopg2\__init__.py", line 122, in connect
    conn = _connect(dsn, connection_factory=connection_factory, **kwasync)
           ^^^^^^^^^^^^^^^^^^^^^^^^^^^^^^^^^^^^^^^^^^^^^^^^^^^^^^^^^^^^^^^
django.db.utils.OperationalError: could not translate host name "postgresql-mtaa-wetu0.alwaysdata.net" to address: No such host is known. 

"GET /api/user/profile/ HTTP/1.1" 500 228549
Internal Server Error: /api/user/profile/
Traceback (most recent call last):
  File "C:\Users\user\Documents\react-tailwind\Lib\site-packages\django\db\backends\base\base.py", line 279, in ensure_connection
    self.connect()
  File "C:\Users\user\Documents\react-tailwind\Lib\site-packages\django\utils\asyncio.py", line 26, in inner
    return func(*args, **kwargs)
           ^^^^^^^^^^^^^^^^^^^^^
  File "C:\Users\user\Documents\react-tailwind\Lib\site-packages\django\db\backends\base\base.py", line 256, in connect
    self.connection = self.get_new_connection(conn_params)
                      ^^^^^^^^^^^^^^^^^^^^^^^^^^^^^^^^^^^^
  File "C:\Users\user\Documents\react-tailwind\Lib\site-packages\django\utils\asyncio.py", line 26, in inner
    return func(*args, **kwargs)
           ^^^^^^^^^^^^^^^^^^^^^
  File "C:\Users\user\Documents\react-tailwind\Lib\site-packages\django\db\backends\postgresql\base.py", line 332, in get_new_connection
    connection = self.Database.connect(**conn_params)
                 ^^^^^^^^^^^^^^^^^^^^^^^^^^^^^^^^^^^^
  File "C:\Users\user\Documents\react-tailwind\Lib\site-packages\psycopg2\__init__.py", line 122, in connect
    conn = _connect(dsn, connection_factory=connection_factory, **kwasync)
           ^^^^^^^^^^^^^^^^^^^^^^^^^^^^^^^^^^^^^^^^^^^^^^^^^^^^^^^^^^^^^^^
psycopg2.OperationalError: could not translate host name "postgresql-mtaa-wetu0.alwaysdata.net" to address: No such host is known. 


The above exception was the direct cause of the following exception:

Traceback (most recent call last):
  File "C:\Users\user\Documents\react-tailwind\Lib\site-packages\django\core\handlers\exception.py", line 55, in inner
    response = get_response(request)
               ^^^^^^^^^^^^^^^^^^^^^
  File "C:\Users\user\Documents\react-tailwind\Lib\site-packages\django\core\handlers\base.py", line 197, in _get_response
    response = wrapped_callback(request, *callback_args, **callback_kwargs)
               ^^^^^^^^^^^^^^^^^^^^^^^^^^^^^^^^^^^^^^^^^^^^^^^^^^^^^^^^^^^^
  File "C:\Users\user\Documents\react-tailwind\Lib\site-packages\django\views\decorators\csrf.py", line 65, in _view_wrapper
    return view_func(request, *args, **kwargs)
           ^^^^^^^^^^^^^^^^^^^^^^^^^^^^^^^^^^^
  File "C:\Users\user\Documents\react-tailwind\Lib\site-packages\django\views\generic\base.py", line 104, in view
    return self.dispatch(request, *args, **kwargs)
           ^^^^^^^^^^^^^^^^^^^^^^^^^^^^^^^^^^^^^^^
  File "C:\Users\user\Documents\react-tailwind\Lib\site-packages\rest_framework\views.py", line 509, in dispatch
    response = self.handle_exception(exc)
               ^^^^^^^^^^^^^^^^^^^^^^^^^^
  File "C:\Users\user\Documents\react-tailwind\Lib\site-packages\rest_framework\views.py", line 469, in handle_exception
    self.raise_uncaught_exception(exc)
  File "C:\Users\user\Documents\react-tailwind\Lib\site-packages\rest_framework\views.py", line 480, in raise_uncaught_exception
    raise exc
  File "C:\Users\user\Documents\react-tailwind\Lib\site-packages\rest_framework\views.py", line 497, in dispatch
    self.initial(request, *args, **kwargs)
  File "C:\Users\user\Documents\react-tailwind\Lib\site-packages\rest_framework\views.py", line 414, in initial
    self.perform_authentication(request)
  File "C:\Users\user\Documents\react-tailwind\Lib\site-packages\rest_framework\views.py", line 324, in perform_authentication
    request.user
  File "C:\Users\user\Documents\react-tailwind\Lib\site-packages\rest_framework\request.py", line 231, in user
    self._authenticate()
  File "C:\Users\user\Documents\react-tailwind\Lib\site-packages\rest_framework\request.py", line 384, in _authenticate
    user_auth_tuple = authenticator.authenticate(self)
                      ^^^^^^^^^^^^^^^^^^^^^^^^^^^^^^^^
  File "C:\Users\user\Documents\react-tailwind\Lib\site-packages\rest_framework_simplejwt\authentication.py", line 51, in authenticate
    return self.get_user(validated_token), validated_token
           ^^^^^^^^^^^^^^^^^^^^^^^^^^^^^^
  File "C:\Users\user\Documents\react-tailwind\Lib\site-packages\rest_framework_simplejwt\authentication.py", line 130, in get_user
    user = self.user_model.objects.get(**{api_settings.USER_ID_FIELD: user_id})
           ^^^^^^^^^^^^^^^^^^^^^^^^^^^^^^^^^^^^^^^^^^^^^^^^^^^^^^^^^^^^^^^^^^^^
  File "C:\Users\user\Documents\react-tailwind\Lib\site-packages\django\db\models\manager.py", line 87, in manager_method
    return getattr(self.get_queryset(), name)(*args, **kwargs)
           ^^^^^^^^^^^^^^^^^^^^^^^^^^^^^^^^^^^^^^^^^^^^^^^^^^^
  File "C:\Users\user\Documents\react-tailwind\Lib\site-packages\django\db\models\query.py", line 645, in get
    num = len(clone)
          ^^^^^^^^^^
  File "C:\Users\user\Documents\react-tailwind\Lib\site-packages\django\db\models\query.py", line 382, in __len__
    self._fetch_all()
  File "C:\Users\user\Documents\react-tailwind\Lib\site-packages\django\db\models\query.py", line 1928, in _fetch_all
    self._result_cache = list(self._iterable_class(self))
                         ^^^^^^^^^^^^^^^^^^^^^^^^^^^^^^^^
  File "C:\Users\user\Documents\react-tailwind\Lib\site-packages\django\db\models\query.py", line 91, in __iter__
    results = compiler.execute_sql(
              ^^^^^^^^^^^^^^^^^^^^^
  File "C:\Users\user\Documents\react-tailwind\Lib\site-packages\django\db\models\sql\compiler.py", line 1572, in execute_sql
    cursor = self.connection.cursor()
             ^^^^^^^^^^^^^^^^^^^^^^^^
  File "C:\Users\user\Documents\react-tailwind\Lib\site-packages\django\utils\asyncio.py", line 26, in inner
    return func(*args, **kwargs)
           ^^^^^^^^^^^^^^^^^^^^^
  File "C:\Users\user\Documents\react-tailwind\Lib\site-packages\django\db\backends\base\base.py", line 320, in cursor
    return self._cursor()
           ^^^^^^^^^^^^^^
  File "C:\Users\user\Documents\react-tailwind\Lib\site-packages\django\db\backends\base\base.py", line 296, in _cursor
    self.ensure_connection()
  File "C:\Users\user\Documents\react-tailwind\Lib\site-packages\django\utils\asyncio.py", line 26, in inner
    return func(*args, **kwargs)
           ^^^^^^^^^^^^^^^^^^^^^
  File "C:\Users\user\Documents\react-tailwind\Lib\site-packages\django\db\backends\base\base.py", line 278, in ensure_connection
    with self.wrap_database_errors:
         ^^^^^^^^^^^^^^^^^^^^^^^^^
  File "C:\Users\user\Documents\react-tailwind\Lib\site-packages\django\db\utils.py", line 91, in __exit__
    raise dj_exc_value.with_traceback(traceback) from exc_value
  File "C:\Users\user\Documents\react-tailwind\Lib\site-packages\django\db\backends\base\base.py", line 279, in ensure_connection
    self.connect()
  File "C:\Users\user\Documents\react-tailwind\Lib\site-packages\django\utils\asyncio.py", line 26, in inner
    return func(*args, **kwargs)
           ^^^^^^^^^^^^^^^^^^^^^
  File "C:\Users\user\Documents\react-tailwind\Lib\site-packages\django\db\backends\base\base.py", line 256, in connect
    self.connection = self.get_new_connection(conn_params)
                      ^^^^^^^^^^^^^^^^^^^^^^^^^^^^^^^^^^^^
  File "C:\Users\user\Documents\react-tailwind\Lib\site-packages\django\utils\asyncio.py", line 26, in inner
    return func(*args, **kwargs)
           ^^^^^^^^^^^^^^^^^^^^^
  File "C:\Users\user\Documents\react-tailwind\Lib\site-packages\django\db\backends\postgresql\base.py", line 332, in get_new_connection
    connection = self.Database.connect(**conn_params)
                 ^^^^^^^^^^^^^^^^^^^^^^^^^^^^^^^^^^^^
  File "C:\Users\user\Documents\react-tailwind\Lib\site-packages\psycopg2\__init__.py", line 122, in connect
    conn = _connect(dsn, connection_factory=connection_factory, **kwasync)
           ^^^^^^^^^^^^^^^^^^^^^^^^^^^^^^^^^^^^^^^^^^^^^^^^^^^^^^^^^^^^^^^
django.db.utils.OperationalError: could not translate host name "postgresql-mtaa-wetu0.alwaysdata.net" to address: No such host is known. 

"GET /api/user/profile/ HTTP/1.1" 500 228549
Internal Server Error: /api/auth/login/
Traceback (most recent call last):
  File "C:\Users\user\Documents\react-tailwind\Lib\site-packages\django\db\backends\base\base.py", line 279, in ensure_connection
    self.connect()
  File "C:\Users\user\Documents\react-tailwind\Lib\site-packages\django\utils\asyncio.py", line 26, in inner
    return func(*args, **kwargs)
           ^^^^^^^^^^^^^^^^^^^^^
  File "C:\Users\user\Documents\react-tailwind\Lib\site-packages\django\db\backends\base\base.py", line 256, in connect
    self.connection = self.get_new_connection(conn_params)
                      ^^^^^^^^^^^^^^^^^^^^^^^^^^^^^^^^^^^^
  File "C:\Users\user\Documents\react-tailwind\Lib\site-packages\django\utils\asyncio.py", line 26, in inner
    return func(*args, **kwargs)
           ^^^^^^^^^^^^^^^^^^^^^
  File "C:\Users\user\Documents\react-tailwind\Lib\site-packages\django\db\backends\postgresql\base.py", line 332, in get_new_connection
    connection = self.Database.connect(**conn_params)
                 ^^^^^^^^^^^^^^^^^^^^^^^^^^^^^^^^^^^^
  File "C:\Users\user\Documents\react-tailwind\Lib\site-packages\psycopg2\__init__.py", line 122, in connect
    conn = _connect(dsn, connection_factory=connection_factory, **kwasync)
           ^^^^^^^^^^^^^^^^^^^^^^^^^^^^^^^^^^^^^^^^^^^^^^^^^^^^^^^^^^^^^^^
psycopg2.OperationalError: could not translate host name "postgresql-mtaa-wetu0.alwaysdata.net" to address: No such host is known. 


The above exception was the direct cause of the following exception:

Traceback (most recent call last):
  File "C:\Users\user\Documents\react-tailwind\Lib\site-packages\django\core\handlers\exception.py", line 55, in inner
    response = get_response(request)
               ^^^^^^^^^^^^^^^^^^^^^
  File "C:\Users\user\Documents\react-tailwind\Lib\site-packages\django\core\handlers\base.py", line 197, in _get_response
    response = wrapped_callback(request, *callback_args, **callback_kwargs)
               ^^^^^^^^^^^^^^^^^^^^^^^^^^^^^^^^^^^^^^^^^^^^^^^^^^^^^^^^^^^^
  File "C:\Users\user\Documents\react-tailwind\Lib\site-packages\django\views\decorators\csrf.py", line 65, in _view_wrapper
    return view_func(request, *args, **kwargs)
           ^^^^^^^^^^^^^^^^^^^^^^^^^^^^^^^^^^^
  File "C:\Users\user\Documents\react-tailwind\Lib\site-packages\django\views\generic\base.py", line 104, in view
    return self.dispatch(request, *args, **kwargs)
           ^^^^^^^^^^^^^^^^^^^^^^^^^^^^^^^^^^^^^^^
  File "C:\Users\user\Documents\react-tailwind\Lib\site-packages\rest_framework\views.py", line 509, in dispatch
    response = self.handle_exception(exc)
               ^^^^^^^^^^^^^^^^^^^^^^^^^^
  File "C:\Users\user\Documents\react-tailwind\Lib\site-packages\rest_framework\views.py", line 469, in handle_exception
    self.raise_uncaught_exception(exc)
  File "C:\Users\user\Documents\react-tailwind\Lib\site-packages\rest_framework\views.py", line 480, in raise_uncaught_exception
    raise exc
  File "C:\Users\user\Documents\react-tailwind\Lib\site-packages\rest_framework\views.py", line 506, in dispatch
    response = handler(request, *args, **kwargs)
               ^^^^^^^^^^^^^^^^^^^^^^^^^^^^^^^^^
  File "C:\Users\user\Documents\react-tailwind\Lib\site-packages\rest_framework\decorators.py", line 50, in handler
    return func(*args, **kwargs)
           ^^^^^^^^^^^^^^^^^^^^^
  File "C:\Users\user\Documents\react-tailwind\backendMtaawetuApi\coreApi\views.py", line 73, in login_user
    if serializer.is_valid():
       ^^^^^^^^^^^^^^^^^^^^^
  File "C:\Users\user\Documents\react-tailwind\Lib\site-packages\rest_framework\serializers.py", line 223, in is_valid
    self._validated_data = self.run_validation(self.initial_data)
                           ^^^^^^^^^^^^^^^^^^^^^^^^^^^^^^^^^^^^^^
  File "C:\Users\user\Documents\react-tailwind\Lib\site-packages\rest_framework\serializers.py", line 445, in run_validation
    value = self.validate(value)
            ^^^^^^^^^^^^^^^^^^^^
  File "C:\Users\user\Documents\react-tailwind\backendMtaawetuApi\coreApi\serializers.py", line 56, in validate
    user = authenticate(username=email, password=password)
           ^^^^^^^^^^^^^^^^^^^^^^^^^^^^^^^^^^^^^^^^^^^^^^^
  File "C:\Users\user\Documents\react-tailwind\Lib\site-packages\django\views\decorators\debug.py", line 75, in sensitive_variables_wrapper
    return func(*func_args, **func_kwargs)
           ^^^^^^^^^^^^^^^^^^^^^^^^^^^^^^^
  File "C:\Users\user\Documents\react-tailwind\Lib\site-packages\django\contrib\auth\__init__.py", line 79, in authenticate
    user = backend.authenticate(request, **credentials)
           ^^^^^^^^^^^^^^^^^^^^^^^^^^^^^^^^^^^^^^^^^^^^
  File "C:\Users\user\Documents\react-tailwind\Lib\site-packages\django\contrib\auth\backends.py", line 42, in authenticate
    user = UserModel._default_manager.get_by_natural_key(username)
           ^^^^^^^^^^^^^^^^^^^^^^^^^^^^^^^^^^^^^^^^^^^^^^^^^^^^^^^
  File "C:\Users\user\Documents\react-tailwind\Lib\site-packages\django\contrib\auth\base_user.py", line 37, in get_by_natural_key
    return self.get(**{self.model.USERNAME_FIELD: username})
           ^^^^^^^^^^^^^^^^^^^^^^^^^^^^^^^^^^^^^^^^^^^^^^^^^
  File "C:\Users\user\Documents\react-tailwind\Lib\site-packages\django\db\models\manager.py", line 87, in manager_method
    return getattr(self.get_queryset(), name)(*args, **kwargs)
           ^^^^^^^^^^^^^^^^^^^^^^^^^^^^^^^^^^^^^^^^^^^^^^^^^^^
  File "C:\Users\user\Documents\react-tailwind\Lib\site-packages\django\db\models\query.py", line 645, in get
    num = len(clone)
          ^^^^^^^^^^
  File "C:\Users\user\Documents\react-tailwind\Lib\site-packages\django\db\models\query.py", line 382, in __len__
    self._fetch_all()
  File "C:\Users\user\Documents\react-tailwind\Lib\site-packages\django\db\models\query.py", line 1928, in _fetch_all
    self._result_cache = list(self._iterable_class(self))
                         ^^^^^^^^^^^^^^^^^^^^^^^^^^^^^^^^
  File "C:\Users\user\Documents\react-tailwind\Lib\site-packages\django\db\models\query.py", line 91, in __iter__
    results = compiler.execute_sql(
              ^^^^^^^^^^^^^^^^^^^^^
  File "C:\Users\user\Documents\react-tailwind\Lib\site-packages\django\db\models\sql\compiler.py", line 1572, in execute_sql
    cursor = self.connection.cursor()
             ^^^^^^^^^^^^^^^^^^^^^^^^
  File "C:\Users\user\Documents\react-tailwind\Lib\site-packages\django\utils\asyncio.py", line 26, in inner
    return func(*args, **kwargs)
           ^^^^^^^^^^^^^^^^^^^^^
  File "C:\Users\user\Documents\react-tailwind\Lib\site-packages\django\db\backends\base\base.py", line 320, in cursor
    return self._cursor()
           ^^^^^^^^^^^^^^
  File "C:\Users\user\Documents\react-tailwind\Lib\site-packages\django\db\backends\base\base.py", line 296, in _cursor
    self.ensure_connection()
  File "C:\Users\user\Documents\react-tailwind\Lib\site-packages\django\utils\asyncio.py", line 26, in inner
    return func(*args, **kwargs)
           ^^^^^^^^^^^^^^^^^^^^^
  File "C:\Users\user\Documents\react-tailwind\Lib\site-packages\django\db\backends\base\base.py", line 278, in ensure_connection
    with self.wrap_database_errors:
         ^^^^^^^^^^^^^^^^^^^^^^^^^
  File "C:\Users\user\Documents\react-tailwind\Lib\site-packages\django\db\utils.py", line 91, in __exit__
    raise dj_exc_value.with_traceback(traceback) from exc_value
  File "C:\Users\user\Documents\react-tailwind\Lib\site-packages\django\db\backends\base\base.py", line 279, in ensure_connection
    self.connect()
  File "C:\Users\user\Documents\react-tailwind\Lib\site-packages\django\utils\asyncio.py", line 26, in inner
    return func(*args, **kwargs)
           ^^^^^^^^^^^^^^^^^^^^^
  File "C:\Users\user\Documents\react-tailwind\Lib\site-packages\django\db\backends\base\base.py", line 256, in connect
    self.connection = self.get_new_connection(conn_params)
                      ^^^^^^^^^^^^^^^^^^^^^^^^^^^^^^^^^^^^
  File "C:\Users\user\Documents\react-tailwind\Lib\site-packages\django\utils\asyncio.py", line 26, in inner
    return func(*args, **kwargs)
           ^^^^^^^^^^^^^^^^^^^^^
  File "C:\Users\user\Documents\react-tailwind\Lib\site-packages\django\db\backends\postgresql\base.py", line 332, in get_new_connection
    connection = self.Database.connect(**conn_params)
                 ^^^^^^^^^^^^^^^^^^^^^^^^^^^^^^^^^^^^
  File "C:\Users\user\Documents\react-tailwind\Lib\site-packages\psycopg2\__init__.py", line 122, in connect
    conn = _connect(dsn, connection_factory=connection_factory, **kwasync)
           ^^^^^^^^^^^^^^^^^^^^^^^^^^^^^^^^^^^^^^^^^^^^^^^^^^^^^^^^^^^^^^^
django.db.utils.OperationalError: could not translate host name "postgresql-mtaa-wetu0.alwaysdata.net" to address: No such host is known. 

"POST /api/auth/login/ HTTP/1.1" 500 241946
Internal Server Error: /api/auth/login/
Traceback (most recent call last):
  File "C:\Users\user\Documents\react-tailwind\Lib\site-packages\django\db\backends\base\base.py", line 279, in ensure_connection
    self.connect()
  File "C:\Users\user\Documents\react-tailwind\Lib\site-packages\django\utils\asyncio.py", line 26, in inner
    return func(*args, **kwargs)
           ^^^^^^^^^^^^^^^^^^^^^
  File "C:\Users\user\Documents\react-tailwind\Lib\site-packages\django\db\backends\base\base.py", line 256, in connect
    self.connection = self.get_new_connection(conn_params)
                      ^^^^^^^^^^^^^^^^^^^^^^^^^^^^^^^^^^^^
  File "C:\Users\user\Documents\react-tailwind\Lib\site-packages\django\utils\asyncio.py", line 26, in inner
    return func(*args, **kwargs)
           ^^^^^^^^^^^^^^^^^^^^^
  File "C:\Users\user\Documents\react-tailwind\Lib\site-packages\django\db\backends\postgresql\base.py", line 332, in get_new_connection
    connection = self.Database.connect(**conn_params)
                 ^^^^^^^^^^^^^^^^^^^^^^^^^^^^^^^^^^^^
  File "C:\Users\user\Documents\react-tailwind\Lib\site-packages\psycopg2\__init__.py", line 122, in connect
    conn = _connect(dsn, connection_factory=connection_factory, **kwasync)
           ^^^^^^^^^^^^^^^^^^^^^^^^^^^^^^^^^^^^^^^^^^^^^^^^^^^^^^^^^^^^^^^
psycopg2.OperationalError: could not translate host name "postgresql-mtaa-wetu0.alwaysdata.net" to address: No such host is known. 


The above exception was the direct cause of the following exception:

Traceback (most recent call last):
  File "C:\Users\user\Documents\react-tailwind\Lib\site-packages\django\core\handlers\exception.py", line 55, in inner
    response = get_response(request)
               ^^^^^^^^^^^^^^^^^^^^^
  File "C:\Users\user\Documents\react-tailwind\Lib\site-packages\django\core\handlers\base.py", line 197, in _get_response
    response = wrapped_callback(request, *callback_args, **callback_kwargs)
               ^^^^^^^^^^^^^^^^^^^^^^^^^^^^^^^^^^^^^^^^^^^^^^^^^^^^^^^^^^^^
  File "C:\Users\user\Documents\react-tailwind\Lib\site-packages\django\views\decorators\csrf.py", line 65, in _view_wrapper
    return view_func(request, *args, **kwargs)
           ^^^^^^^^^^^^^^^^^^^^^^^^^^^^^^^^^^^
  File "C:\Users\user\Documents\react-tailwind\Lib\site-packages\django\views\generic\base.py", line 104, in view
    return self.dispatch(request, *args, **kwargs)
           ^^^^^^^^^^^^^^^^^^^^^^^^^^^^^^^^^^^^^^^
  File "C:\Users\user\Documents\react-tailwind\Lib\site-packages\rest_framework\views.py", line 509, in dispatch
    response = self.handle_exception(exc)
               ^^^^^^^^^^^^^^^^^^^^^^^^^^
  File "C:\Users\user\Documents\react-tailwind\Lib\site-packages\rest_framework\views.py", line 469, in handle_exception
    self.raise_uncaught_exception(exc)
  File "C:\Users\user\Documents\react-tailwind\Lib\site-packages\rest_framework\views.py", line 480, in raise_uncaught_exception
    raise exc
  File "C:\Users\user\Documents\react-tailwind\Lib\site-packages\rest_framework\views.py", line 506, in dispatch
    response = handler(request, *args, **kwargs)
               ^^^^^^^^^^^^^^^^^^^^^^^^^^^^^^^^^
  File "C:\Users\user\Documents\react-tailwind\Lib\site-packages\rest_framework\decorators.py", line 50, in handler
    return func(*args, **kwargs)
           ^^^^^^^^^^^^^^^^^^^^^
  File "C:\Users\user\Documents\react-tailwind\backendMtaawetuApi\coreApi\views.py", line 73, in login_user
    if serializer.is_valid():
       ^^^^^^^^^^^^^^^^^^^^^
  File "C:\Users\user\Documents\react-tailwind\Lib\site-packages\rest_framework\serializers.py", line 223, in is_valid
    self._validated_data = self.run_validation(self.initial_data)
                           ^^^^^^^^^^^^^^^^^^^^^^^^^^^^^^^^^^^^^^
  File "C:\Users\user\Documents\react-tailwind\Lib\site-packages\rest_framework\serializers.py", line 445, in run_validation
    value = self.validate(value)
            ^^^^^^^^^^^^^^^^^^^^
  File "C:\Users\user\Documents\react-tailwind\backendMtaawetuApi\coreApi\serializers.py", line 56, in validate
    user = authenticate(username=email, password=password)
           ^^^^^^^^^^^^^^^^^^^^^^^^^^^^^^^^^^^^^^^^^^^^^^^
  File "C:\Users\user\Documents\react-tailwind\Lib\site-packages\django\views\decorators\debug.py", line 75, in sensitive_variables_wrapper
    return func(*func_args, **func_kwargs)
           ^^^^^^^^^^^^^^^^^^^^^^^^^^^^^^^
  File "C:\Users\user\Documents\react-tailwind\Lib\site-packages\django\contrib\auth\__init__.py", line 79, in authenticate
    user = backend.authenticate(request, **credentials)
           ^^^^^^^^^^^^^^^^^^^^^^^^^^^^^^^^^^^^^^^^^^^^
  File "C:\Users\user\Documents\react-tailwind\Lib\site-packages\django\contrib\auth\backends.py", line 42, in authenticate
    user = UserModel._default_manager.get_by_natural_key(username)
           ^^^^^^^^^^^^^^^^^^^^^^^^^^^^^^^^^^^^^^^^^^^^^^^^^^^^^^^
  File "C:\Users\user\Documents\react-tailwind\Lib\site-packages\django\contrib\auth\base_user.py", line 37, in get_by_natural_key
    return self.get(**{self.model.USERNAME_FIELD: username})
           ^^^^^^^^^^^^^^^^^^^^^^^^^^^^^^^^^^^^^^^^^^^^^^^^^
  File "C:\Users\user\Documents\react-tailwind\Lib\site-packages\django\db\models\manager.py", line 87, in manager_method
    return getattr(self.get_queryset(), name)(*args, **kwargs)
           ^^^^^^^^^^^^^^^^^^^^^^^^^^^^^^^^^^^^^^^^^^^^^^^^^^^
  File "C:\Users\user\Documents\react-tailwind\Lib\site-packages\django\db\models\query.py", line 645, in get
    num = len(clone)
          ^^^^^^^^^^
  File "C:\Users\user\Documents\react-tailwind\Lib\site-packages\django\db\models\query.py", line 382, in __len__
    self._fetch_all()
  File "C:\Users\user\Documents\react-tailwind\Lib\site-packages\django\db\models\query.py", line 1928, in _fetch_all
    self._result_cache = list(self._iterable_class(self))
                         ^^^^^^^^^^^^^^^^^^^^^^^^^^^^^^^^
  File "C:\Users\user\Documents\react-tailwind\Lib\site-packages\django\db\models\query.py", line 91, in __iter__
    results = compiler.execute_sql(
              ^^^^^^^^^^^^^^^^^^^^^
  File "C:\Users\user\Documents\react-tailwind\Lib\site-packages\django\db\models\sql\compiler.py", line 1572, in execute_sql
    cursor = self.connection.cursor()
             ^^^^^^^^^^^^^^^^^^^^^^^^
  File "C:\Users\user\Documents\react-tailwind\Lib\site-packages\django\utils\asyncio.py", line 26, in inner
    return func(*args, **kwargs)
           ^^^^^^^^^^^^^^^^^^^^^
  File "C:\Users\user\Documents\react-tailwind\Lib\site-packages\django\db\backends\base\base.py", line 320, in cursor
    return self._cursor()
           ^^^^^^^^^^^^^^
  File "C:\Users\user\Documents\react-tailwind\Lib\site-packages\django\db\backends\base\base.py", line 296, in _cursor
    self.ensure_connection()
  File "C:\Users\user\Documents\react-tailwind\Lib\site-packages\django\utils\asyncio.py", line 26, in inner
    return func(*args, **kwargs)
           ^^^^^^^^^^^^^^^^^^^^^
  File "C:\Users\user\Documents\react-tailwind\Lib\site-packages\django\db\backends\base\base.py", line 278, in ensure_connection
    with self.wrap_database_errors:
         ^^^^^^^^^^^^^^^^^^^^^^^^^
  File "C:\Users\user\Documents\react-tailwind\Lib\site-packages\django\db\utils.py", line 91, in __exit__
    raise dj_exc_value.with_traceback(traceback) from exc_value
  File "C:\Users\user\Documents\react-tailwind\Lib\site-packages\django\db\backends\base\base.py", line 279, in ensure_connection
    self.connect()
  File "C:\Users\user\Documents\react-tailwind\Lib\site-packages\django\utils\asyncio.py", line 26, in inner
    return func(*args, **kwargs)
           ^^^^^^^^^^^^^^^^^^^^^
  File "C:\Users\user\Documents\react-tailwind\Lib\site-packages\django\db\backends\base\base.py", line 256, in connect
    self.connection = self.get_new_connection(conn_params)
                      ^^^^^^^^^^^^^^^^^^^^^^^^^^^^^^^^^^^^
  File "C:\Users\user\Documents\react-tailwind\Lib\site-packages\django\utils\asyncio.py", line 26, in inner
    return func(*args, **kwargs)
           ^^^^^^^^^^^^^^^^^^^^^
  File "C:\Users\user\Documents\react-tailwind\Lib\site-packages\django\db\backends\postgresql\base.py", line 332, in get_new_connection
    connection = self.Database.connect(**conn_params)
                 ^^^^^^^^^^^^^^^^^^^^^^^^^^^^^^^^^^^^
  File "C:\Users\user\Documents\react-tailwind\Lib\site-packages\psycopg2\__init__.py", line 122, in connect
    conn = _connect(dsn, connection_factory=connection_factory, **kwasync)
           ^^^^^^^^^^^^^^^^^^^^^^^^^^^^^^^^^^^^^^^^^^^^^^^^^^^^^^^^^^^^^^^
django.db.utils.OperationalError: could not translate host name "postgresql-mtaa-wetu0.alwaysdata.net" to address: No such host is known. 

"POST /api/auth/login/ HTTP/1.1" 500 241946
Internal Server Error: /api/auth/login/
Traceback (most recent call last):
  File "C:\Users\user\Documents\react-tailwind\Lib\site-packages\django\db\backends\base\base.py", line 279, in ensure_connection
    self.connect()
  File "C:\Users\user\Documents\react-tailwind\Lib\site-packages\django\utils\asyncio.py", line 26, in inner
    return func(*args, **kwargs)
           ^^^^^^^^^^^^^^^^^^^^^
  File "C:\Users\user\Documents\react-tailwind\Lib\site-packages\django\db\backends\base\base.py", line 256, in connect
    self.connection = self.get_new_connection(conn_params)
                      ^^^^^^^^^^^^^^^^^^^^^^^^^^^^^^^^^^^^
  File "C:\Users\user\Documents\react-tailwind\Lib\site-packages\django\utils\asyncio.py", line 26, in inner
    return func(*args, **kwargs)
           ^^^^^^^^^^^^^^^^^^^^^
  File "C:\Users\user\Documents\react-tailwind\Lib\site-packages\django\db\backends\postgresql\base.py", line 332, in get_new_connection
    connection = self.Database.connect(**conn_params)
                 ^^^^^^^^^^^^^^^^^^^^^^^^^^^^^^^^^^^^
  File "C:\Users\user\Documents\react-tailwind\Lib\site-packages\psycopg2\__init__.py", line 122, in connect
    conn = _connect(dsn, connection_factory=connection_factory, **kwasync)
           ^^^^^^^^^^^^^^^^^^^^^^^^^^^^^^^^^^^^^^^^^^^^^^^^^^^^^^^^^^^^^^^
psycopg2.OperationalError: could not translate host name "postgresql-mtaa-wetu0.alwaysdata.net" to address: No such host is known. 


The above exception was the direct cause of the following exception:

Traceback (most recent call last):
  File "C:\Users\user\Documents\react-tailwind\Lib\site-packages\django\core\handlers\exception.py", line 55, in inner
    response = get_response(request)
               ^^^^^^^^^^^^^^^^^^^^^
  File "C:\Users\user\Documents\react-tailwind\Lib\site-packages\django\core\handlers\base.py", line 197, in _get_response
    response = wrapped_callback(request, *callback_args, **callback_kwargs)
               ^^^^^^^^^^^^^^^^^^^^^^^^^^^^^^^^^^^^^^^^^^^^^^^^^^^^^^^^^^^^
  File "C:\Users\user\Documents\react-tailwind\Lib\site-packages\django\views\decorators\csrf.py", line 65, in _view_wrapper
    return view_func(request, *args, **kwargs)
           ^^^^^^^^^^^^^^^^^^^^^^^^^^^^^^^^^^^
  File "C:\Users\user\Documents\react-tailwind\Lib\site-packages\django\views\generic\base.py", line 104, in view
    return self.dispatch(request, *args, **kwargs)
           ^^^^^^^^^^^^^^^^^^^^^^^^^^^^^^^^^^^^^^^
  File "C:\Users\user\Documents\react-tailwind\Lib\site-packages\rest_framework\views.py", line 509, in dispatch
    response = self.handle_exception(exc)
               ^^^^^^^^^^^^^^^^^^^^^^^^^^
  File "C:\Users\user\Documents\react-tailwind\Lib\site-packages\rest_framework\views.py", line 469, in handle_exception
    self.raise_uncaught_exception(exc)
  File "C:\Users\user\Documents\react-tailwind\Lib\site-packages\rest_framework\views.py", line 480, in raise_uncaught_exception
    raise exc
  File "C:\Users\user\Documents\react-tailwind\Lib\site-packages\rest_framework\views.py", line 506, in dispatch
    response = handler(request, *args, **kwargs)
               ^^^^^^^^^^^^^^^^^^^^^^^^^^^^^^^^^
  File "C:\Users\user\Documents\react-tailwind\Lib\site-packages\rest_framework\decorators.py", line 50, in handler
    return func(*args, **kwargs)
           ^^^^^^^^^^^^^^^^^^^^^
  File "C:\Users\user\Documents\react-tailwind\backendMtaawetuApi\coreApi\views.py", line 73, in login_user
    if serializer.is_valid():
       ^^^^^^^^^^^^^^^^^^^^^
  File "C:\Users\user\Documents\react-tailwind\Lib\site-packages\rest_framework\serializers.py", line 223, in is_valid
    self._validated_data = self.run_validation(self.initial_data)
                           ^^^^^^^^^^^^^^^^^^^^^^^^^^^^^^^^^^^^^^
  File "C:\Users\user\Documents\react-tailwind\Lib\site-packages\rest_framework\serializers.py", line 445, in run_validation
    value = self.validate(value)
            ^^^^^^^^^^^^^^^^^^^^
  File "C:\Users\user\Documents\react-tailwind\backendMtaawetuApi\coreApi\serializers.py", line 56, in validate
    user = authenticate(username=email, password=password)
           ^^^^^^^^^^^^^^^^^^^^^^^^^^^^^^^^^^^^^^^^^^^^^^^
  File "C:\Users\user\Documents\react-tailwind\Lib\site-packages\django\views\decorators\debug.py", line 75, in sensitive_variables_wrapper
    return func(*func_args, **func_kwargs)
           ^^^^^^^^^^^^^^^^^^^^^^^^^^^^^^^
  File "C:\Users\user\Documents\react-tailwind\Lib\site-packages\django\contrib\auth\__init__.py", line 79, in authenticate
    user = backend.authenticate(request, **credentials)
           ^^^^^^^^^^^^^^^^^^^^^^^^^^^^^^^^^^^^^^^^^^^^
  File "C:\Users\user\Documents\react-tailwind\Lib\site-packages\django\contrib\auth\backends.py", line 42, in authenticate
    user = UserModel._default_manager.get_by_natural_key(username)
           ^^^^^^^^^^^^^^^^^^^^^^^^^^^^^^^^^^^^^^^^^^^^^^^^^^^^^^^
  File "C:\Users\user\Documents\react-tailwind\Lib\site-packages\django\contrib\auth\base_user.py", line 37, in get_by_natural_key
    return self.get(**{self.model.USERNAME_FIELD: username})
           ^^^^^^^^^^^^^^^^^^^^^^^^^^^^^^^^^^^^^^^^^^^^^^^^^
  File "C:\Users\user\Documents\react-tailwind\Lib\site-packages\django\db\models\manager.py", line 87, in manager_method
    return getattr(self.get_queryset(), name)(*args, **kwargs)
           ^^^^^^^^^^^^^^^^^^^^^^^^^^^^^^^^^^^^^^^^^^^^^^^^^^^
  File "C:\Users\user\Documents\react-tailwind\Lib\site-packages\django\db\models\query.py", line 645, in get
    num = len(clone)
          ^^^^^^^^^^
  File "C:\Users\user\Documents\react-tailwind\Lib\site-packages\django\db\models\query.py", line 382, in __len__
    self._fetch_all()
  File "C:\Users\user\Documents\react-tailwind\Lib\site-packages\django\db\models\query.py", line 1928, in _fetch_all
    self._result_cache = list(self._iterable_class(self))
                         ^^^^^^^^^^^^^^^^^^^^^^^^^^^^^^^^
  File "C:\Users\user\Documents\react-tailwind\Lib\site-packages\django\db\models\query.py", line 91, in __iter__
    results = compiler.execute_sql(
              ^^^^^^^^^^^^^^^^^^^^^
  File "C:\Users\user\Documents\react-tailwind\Lib\site-packages\django\db\models\sql\compiler.py", line 1572, in execute_sql
    cursor = self.connection.cursor()
             ^^^^^^^^^^^^^^^^^^^^^^^^
  File "C:\Users\user\Documents\react-tailwind\Lib\site-packages\django\utils\asyncio.py", line 26, in inner
    return func(*args, **kwargs)
           ^^^^^^^^^^^^^^^^^^^^^
  File "C:\Users\user\Documents\react-tailwind\Lib\site-packages\django\db\backends\base\base.py", line 320, in cursor
    return self._cursor()
           ^^^^^^^^^^^^^^
  File "C:\Users\user\Documents\react-tailwind\Lib\site-packages\django\db\backends\base\base.py", line 296, in _cursor
    self.ensure_connection()
  File "C:\Users\user\Documents\react-tailwind\Lib\site-packages\django\utils\asyncio.py", line 26, in inner
    return func(*args, **kwargs)
           ^^^^^^^^^^^^^^^^^^^^^
  File "C:\Users\user\Documents\react-tailwind\Lib\site-packages\django\db\backends\base\base.py", line 278, in ensure_connection
    with self.wrap_database_errors:
         ^^^^^^^^^^^^^^^^^^^^^^^^^
  File "C:\Users\user\Documents\react-tailwind\Lib\site-packages\django\db\utils.py", line 91, in __exit__
    raise dj_exc_value.with_traceback(traceback) from exc_value
  File "C:\Users\user\Documents\react-tailwind\Lib\site-packages\django\db\backends\base\base.py", line 279, in ensure_connection
    self.connect()
  File "C:\Users\user\Documents\react-tailwind\Lib\site-packages\django\utils\asyncio.py", line 26, in inner
    return func(*args, **kwargs)
           ^^^^^^^^^^^^^^^^^^^^^
  File "C:\Users\user\Documents\react-tailwind\Lib\site-packages\django\db\backends\base\base.py", line 256, in connect
    self.connection = self.get_new_connection(conn_params)
                      ^^^^^^^^^^^^^^^^^^^^^^^^^^^^^^^^^^^^
  File "C:\Users\user\Documents\react-tailwind\Lib\site-packages\django\utils\asyncio.py", line 26, in inner
    return func(*args, **kwargs)
           ^^^^^^^^^^^^^^^^^^^^^
  File "C:\Users\user\Documents\react-tailwind\Lib\site-packages\django\db\backends\postgresql\base.py", line 332, in get_new_connection
    connection = self.Database.connect(**conn_params)
                 ^^^^^^^^^^^^^^^^^^^^^^^^^^^^^^^^^^^^
  File "C:\Users\user\Documents\react-tailwind\Lib\site-packages\psycopg2\__init__.py", line 122, in connect
    conn = _connect(dsn, connection_factory=connection_factory, **kwasync)
           ^^^^^^^^^^^^^^^^^^^^^^^^^^^^^^^^^^^^^^^^^^^^^^^^^^^^^^^^^^^^^^^
django.db.utils.OperationalError: could not translate host name "postgresql-mtaa-wetu0.alwaysdata.net" to address: No such host is known. 

"POST /api/auth/login/ HTTP/1.1" 500 241946
